Workbook

Sheet Graphs
A1: Painel - Terras agrícolas: preços, retornos e índice (estilo NCREIF)
A2: Todos os gráficos leem as fórmulas das abas Asset Value, Rent e Returns. Dados auxiliares dos gráficos estão abaixo (linha 84 em diante).
A84: DADOS DOS GRÁFICOS (fórmulas)
A86: Ano | B86: 2008 | C86: =B86+1 -> 2009 | D86: =C86+1 -> 2010 | E86: =D86+1 -> 2011 | F86: =E86+1 -> 2012 | G86: =F86+1 -> 2013 | H86: =G86+1 -> 2014 | I86: =H86+1 -> 2015
A87: Preço médio da terra (R$/ha) | B87: =SUMIFS('Asset Value'!$F$4:$F$500,'Asset Value'!$B$4:$B$500,B$86)/SUMIFS('Asset Value'!$D$4:$D$500,'Asset Value'!$B$4:$B$500,B$86) -> 6546.9425 | C87: =SUMIFS('Asset Value'!$F$4:$F$500,'Asset Value'!$B$4:$B$500,C$86)/SUMIFS('Asset Value'!$D$4:$D$500,'Asset Value'!$B$4:$B$500,C$86) -> 6865.2147 | D87: =SUMIFS('Asset Value'!$F$4:$F$500,'Asset Value'!$B$4:$B$500,D$86)/SUMIFS('Asset Value'!$D$4:$D$500,'Asset Value'!$B$4:$B$500,D$86) -> 6530.6176 | E87: =SUMIFS('Asset Value'!$F$4:$F$500,'Asset Value'!$B$4:$B$500,E$86)/SUMIFS('Asset Value'!$D$4:$D$500,'Asset Value'!$B$4:$B$500,E$86) -> 7875.1827 | F87: =SUMIFS('Asset Value'!$F$4:$F$500,'Asset Value'!$B$4:$B$500,F$86)/SUMIFS('Asset Value'!$D$4:$D$500,'Asset Value'!$B$4:$B$500,F$86) -> 7836.6341 | G87: =SUMIFS('Asset Value'!$F$4:$F$500,'Asset Value'!$B$4:$B$500,G$86)/SUMIFS('Asset Value'!$D$4:$D$500,'Asset Value'!$B$4:$B$500,G$86) -> 9206.3811 | H87: =SUMIFS('Asset Value'!$F$4:$F$500,'Asset Value'!$B$4:$B$500,H$86)/SUMIFS('Asset Value'!$D$4:$D$500,'Asset Value'!$B$4:$B$500,H$86) -> 10488.376 | I87: =SUMIFS('Asset Value'!$F$4:$F$500,'Asset Value'!$B$4:$B$500,I$86)/SUMIFS('Asset Value'!$D$4:$D$500,'Asset Value'!$B$4:$B$500,I$86) -> 11019.247
A88: Preço médio da terra (US$/ha) | B88: =SUMIFS('Asset Value'!$I$4:$I$500,'Asset Value'!$B$4:$B$500,B$86)/SUMIFS('Asset Value'!$D$4:$D$500,'Asset Value'!$B$4:$B$500,B$86) -> 3882.2003 | C88: =SUMIFS('Asset Value'!$I$4:$I$500,'Asset Value'!$B$4:$B$500,C$86)/SUMIFS('Asset Value'!$D$4:$D$500,'Asset Value'!$B$4:$B$500,C$86) -> 3409.4233 | D88: =SUMIFS('Asset Value'!$I$4:$I$500,'Asset Value'!$B$4:$B$500,D$86)/SUMIFS('Asset Value'!$D$4:$D$500,'Asset Value'!$B$4:$B$500,D$86) -> 3775.3599 | E88: =SUMIFS('Asset Value'!$I$4:$I$500,'Asset Value'!$B$4:$B$500,E$86)/SUMIFS('Asset Value'!$D$4:$D$500,'Asset Value'!$B$4:$B$500,E$86) -> 4890.5066 | F88: =SUMIFS('Asset Value'!$I$4:$I$500,'Asset Value'!$B$4:$B$500,F$86)/SUMIFS('Asset Value'!$D$4:$D$500,'Asset Value'!$B$4:$B$500,F$86) -> 3858.8902 | G88: =SUMIFS('Asset Value'!$I$4:$I$500,'Asset Value'!$B$4:$B$500,G$86)/SUMIFS('Asset Value'!$D$4:$D$500,'Asset Value'!$B$4:$B$500,G$86) -> 4050.4999 | H88: =SUMIFS('Asset Value'!$I$4:$I$500,'Asset Value'!$B$4:$B$500,H$86)/SUMIFS('Asset Value'!$D$4:$D$500,'Asset Value'!$B$4:$B$500,H$86) -> 4626.9526 | I88: =SUMIFS('Asset Value'!$I$4:$I$500,'Asset Value'!$B$4:$B$500,I$86)/SUMIFS('Asset Value'!$D$4:$D$500,'Asset Value'!$B$4:$B$500,I$86) -> 3247.2586
A89: Valor de mercado do portfólio (R$ mm) | B89: =SUMIFS(Returns!$E$120:$E$239,Returns!$B$120:$B$239,B$86)/1000 -> 1096.77 | C89: =SUMIFS(Returns!$E$120:$E$239,Returns!$B$120:$B$239,C$86)/1000 -> 1495.69 | D89: =SUMIFS(Returns!$E$120:$E$239,Returns!$B$120:$B$239,D$86)/1000 -> 1500.93 | E89: =SUMIFS(Returns!$E$120:$E$239,Returns!$B$120:$B$239,E$86)/1000 -> 1756.15 | F89: =SUMIFS(Returns!$E$120:$E$239,Returns!$B$120:$B$239,F$86)/1000 -> 2315.6 | G89: =SUMIFS(Returns!$E$120:$E$239,Returns!$B$120:$B$239,G$86)/1000 -> 2678.615 | H89: =SUMIFS(Returns!$E$120:$E$239,Returns!$B$120:$B$239,H$86)/1000 -> 3188.76 | I89: =SUMIFS(Returns!$E$120:$E$239,Returns!$B$120:$B$239,I$86)/1000 -> 3401.84
A90: Valor de mercado do portfólio (US$ mm) | B90: =SUMIFS(Returns!$E$244:$E$363,Returns!$B$244:$B$363,B$86)/1000 -> 650.36172 | C90: =SUMIFS(Returns!$E$244:$E$363,Returns!$B$244:$B$363,C$86)/1000 -> 742.794 | D90: =SUMIFS(Returns!$E$244:$E$363,Returns!$B$244:$B$363,D$86)/1000 -> 867.86057 | E90: =SUMIFS(Returns!$E$244:$E$363,Returns!$B$244:$B$363,E$86)/1000 -> 1090.5732 | F90: =SUMIFS(Returns!$E$244:$E$363,Returns!$B$244:$B$363,F$86)/1000 -> 1140.2403 | G90: =SUMIFS(Returns!$E$244:$E$363,Returns!$B$244:$B$363,G$86)/1000 -> 1178.501 | H90: =SUMIFS(Returns!$E$244:$E$363,Returns!$B$244:$B$363,H$86)/1000 -> 1406.7231 | I90: =SUMIFS(Returns!$E$244:$E$363,Returns!$B$244:$B$363,I$86)/1000 -> 1002.4872
A91: Nº de fazendas avaliadas | B91: =COUNTIFS(Returns!$B$120:$B$239,B$86,Returns!$E$120:$E$239,">0") -> 9 | C91: =COUNTIFS(Returns!$B$120:$B$239,C$86,Returns!$E$120:$E$239,">0") -> 11 | D91: =COUNTIFS(Returns!$B$120:$B$239,D$86,Returns!$E$120:$E$239,">0") -> 11 | E91: =COUNTIFS(Returns!$B$120:$B$239,E$86,Returns!$E$120:$E$239,">0") -> 10 | F91: =COUNTIFS(Returns!$B$120:$B$239,F$86,Returns!$E$120:$E$239,">0") -> 14 | G91: =COUNTIFS(Returns!$B$120:$B$239,G$86,Returns!$E$120:$E$239,">0") -> 14 | H91: =COUNTIFS(Returns!$B$120:$B$239,H$86,Returns!$E$120:$E$239,">0") -> 13 | I91: =COUNTIFS(Returns!$B$120:$B$239,I$86,Returns!$E$120:$E$239,">0") -> 13
A92: PTAX na data da avaliação (R$/US$) | B92: =IFERROR(AVERAGEIFS('Asset Value'!$H$4:$H$500,'Asset Value'!$B$4:$B$500,B$86),0) -> 1.6864 | C92: =IFERROR(AVERAGEIFS('Asset Value'!$H$4:$H$500,'Asset Value'!$B$4:$B$500,C$86),0) -> 2.0136 | D92: =IFERROR(AVERAGEIFS('Asset Value'!$H$4:$H$500,'Asset Value'!$B$4:$B$500,D$86),0) -> 1.7298 | E92: =IFERROR(AVERAGEIFS('Asset Value'!$H$4:$H$500,'Asset Value'!$B$4:$B$500,E$86),0) -> 1.6103 | F92: =IFERROR(AVERAGEIFS('Asset Value'!$H$4:$H$500,'Asset Value'!$B$4:$B$500,F$86),0) -> 2.0308 | G92: =IFERROR(AVERAGEIFS('Asset Value'!$H$4:$H$500,'Asset Value'!$B$4:$B$500,G$86),0) -> 2.2729 | H92: =IFERROR(AVERAGEIFS('Asset Value'!$H$4:$H$500,'Asset Value'!$B$4:$B$500,H$86),0) -> 2.2668 | I92: =IFERROR(AVERAGEIFS('Asset Value'!$H$4:$H$500,'Asset Value'!$B$4:$B$500,I$86),0) -> 3.3934
A93: PTAX em 31/dez (data do rent) (R$/US$) | B93: =IFERROR(AVERAGEIFS(Rent!$F$3:$F$500,Rent!$C$3:$C$500,B$86),0) -> 2.3362 | C93: =IFERROR(AVERAGEIFS(Rent!$F$3:$F$500,Rent!$C$3:$C$500,C$86),0) -> 1.7404 | D93: =IFERROR(AVERAGEIFS(Rent!$F$3:$F$500,Rent!$C$3:$C$500,D$86),0) -> 1.6654 | E93: =IFERROR(AVERAGEIFS(Rent!$F$3:$F$500,Rent!$C$3:$C$500,E$86),0) -> 1.8751 | F93: =IFERROR(AVERAGEIFS(Rent!$F$3:$F$500,Rent!$C$3:$C$500,F$86),0) -> 2.0429 | G93: =IFERROR(AVERAGEIFS(Rent!$F$3:$F$500,Rent!$C$3:$C$500,G$86),0) -> 2.342 | H93: =IFERROR(AVERAGEIFS(Rent!$F$3:$F$500,Rent!$C$3:$C$500,H$86),0) -> 2.6556 | I93: =IFERROR(AVERAGEIFS(Rent!$F$3:$F$500,Rent!$C$3:$C$500,I$86),0) -> 3.9042
A95: Preço da terra por fazenda (R$/ha) = Valor / Área
A96: Farm | B96: =B86 -> 2008 | C96: =C86 -> 2009 | D96: =D86 -> 2010 | E96: =E86 -> 2011 | F96: =F86 -> 2012 | G96: =G86 -> 2013 | H96: =H86 -> 2014 | I96: =I86 -> 2015 | J96: 1º ano | K96: Último ano | L96: R$/ha 1º | M96: R$/ha último | N96: Valorização total | O96: CAGR a.a.
A97: Fazenda Pamplona | B97: =IFERROR(SUMIFS('Asset Value'!$F$4:$F$500,'Asset Value'!$C$4:$C$500,$A97,'Asset Value'!$B$4:$B$500,B$96)/SUMIFS('Asset Value'!$D$4:$D$500,'Asset Value'!$C$4:$C$500,$A97,'Asset Value'!$B$4:$B$500,B$96),0) -> 8401.1934 | C97: =IFERROR(SUMIFS('Asset Value'!$F$4:$F$500,'Asset Value'!$C$4:$C$500,$A97,'Asset Value'!$B$4:$B$500,C$96)/SUMIFS('Asset Value'!$D$4:$D$500,'Asset Value'!$C$4:$C$500,$A97,'Asset Value'!$B$4:$B$500,C$96),0) -> 9255.8793 | D97: =IFERROR(SUMIFS('Asset Value'!$F$4:$F$500,'Asset Value'!$C$4:$C$500,$A97,'Asset Value'!$B$4:$B$500,D$96)/SUMIFS('Asset Value'!$D$4:$D$500,'Asset Value'!$C$4:$C$500,$A97,'Asset Value'!$B$4:$B$500,D$96),0) -> 9608.0496 | E97: =IFERROR(SUMIFS('Asset Value'!$F$4:$F$500,'Asset Value'!$C$4:$C$500,$A97,'Asset Value'!$B$4:$B$500,E$96)/SUMIFS('Asset Value'!$D$4:$D$500,'Asset Value'!$C$4:$C$500,$A97,'Asset Value'!$B$4:$B$500,E$96),0) -> 10504.856 | F97: =IFERROR(SUMIFS('Asset Value'!$F$4:$F$500,'Asset Value'!$C$4:$C$500,$A97,'Asset Value'!$B$4:$B$500,F$96)/SUMIFS('Asset Value'!$D$4:$D$500,'Asset Value'!$C$4:$C$500,$A97,'Asset Value'!$B$4:$B$500,F$96),0) -> 12403.221 | G97: =IFERROR(SUMIFS('Asset Value'!$F$4:$F$500,'Asset Value'!$C$4:$C$500,$A97,'Asset Value'!$B$4:$B$500,G$96)/SUMIFS('Asset Value'!$D$4:$D$500,'Asset Value'!$C$4:$C$500,$A97,'Asset Value'!$B$4:$B$500,G$96),0) -> 12904.343 | H97: =IFERROR(SUMIFS('Asset Value'!$F$4:$F$500,'Asset Value'!$C$4:$C$500,$A97,'Asset Value'!$B$4:$B$500,H$96)/SUMIFS('Asset Value'!$D$4:$D$500,'Asset Value'!$C$4:$C$500,$A97,'Asset Value'!$B$4:$B$500,H$96),0) -> 15526.086 | I97: =IFERROR(SUMIFS('Asset Value'!$F$4:$F$500,'Asset Value'!$C$4:$C$500,$A97,'Asset Value'!$B$4:$B$500,I$96)/SUMIFS('Asset Value'!$D$4:$D$500,'Asset Value'!$C$4:$C$500,$A97,'Asset Value'!$B$4:$B$500,I$96),0) -> 15994.062 | J97: =_xlfn.MINIFS($B$86:$I$86,$B97:$I97,">0") -> 2008 | K97: =_xlfn.MAXIFS($B$86:$I$86,$B97:$I97,">0") -> 2015 | L97: =INDEX($B97:$I97,MATCH(J97,$B$86:$I$86,0)) -> 8401.1934 | M97: =INDEX($B97:$I97,MATCH(K97,$B$86:$I$86,0)) -> 15994.062 | N97: =M97/L97-1 -> 0.90378453 | O97: =IF(K97>J97,(M97/L97)^(1/(K97-J97))-1,"") -> 0.096340352
A98: Fazenda Planalto | B98: =IFERROR(SUMIFS('Asset Value'!$F$4:$F$500,'Asset Value'!$C$4:$C$500,$A98,'Asset Value'!$B$4:$B$500,B$96)/SUMIFS('Asset Value'!$D$4:$D$500,'Asset Value'!$C$4:$C$500,$A98,'Asset Value'!$B$4:$B$500,B$96),0) -> 11876.608 | C98: =IFERROR(SUMIFS('Asset Value'!$F$4:$F$500,'Asset Value'!$C$4:$C$500,$A98,'Asset Value'!$B$4:$B$500,C$96)/SUMIFS('Asset Value'!$D$4:$D$500,'Asset Value'!$C$4:$C$500,$A98,'Asset Value'!$B$4:$B$500,C$96),0) -> 13426.154 | D98: =IFERROR(SUMIFS('Asset Value'!$F$4:$F$500,'Asset Value'!$C$4:$C$500,$A98,'Asset Value'!$B$4:$B$500,D$96)/SUMIFS('Asset Value'!$D$4:$D$500,'Asset Value'!$C$4:$C$500,$A98,'Asset Value'!$B$4:$B$500,D$96),0) -> 13825.615 | E98: =IFERROR(SUMIFS('Asset Value'!$F$4:$F$500,'Asset Value'!$C$4:$C$500,$A98,'Asset Value'!$B$4:$B$500,E$96)/SUMIFS('Asset Value'!$D$4:$D$500,'Asset Value'!$C$4:$C$500,$A98,'Asset Value'!$B$4:$B$500,E$96),0) -> 15709.124 | F98: =IFERROR(SUMIFS('Asset Value'!$F$4:$F$500,'Asset Value'!$C$4:$C$500,$A98,'Asset Value'!$B$4:$B$500,F$96)/SUMIFS('Asset Value'!$D$4:$D$500,'Asset Value'!$C$4:$C$500,$A98,'Asset Value'!$B$4:$B$500,F$96),0) -> 18485.978 | G98: =IFERROR(SUMIFS('Asset Value'!$F$4:$F$500,'Asset Value'!$C$4:$C$500,$A98,'Asset Value'!$B$4:$B$500,G$96)/SUMIFS('Asset Value'!$D$4:$D$500,'Asset Value'!$C$4:$C$500,$A98,'Asset Value'!$B$4:$B$500,G$96),0) -> 19023.456 | H98: =IFERROR(SUMIFS('Asset Value'!$F$4:$F$500,'Asset Value'!$C$4:$C$500,$A98,'Asset Value'!$B$4:$B$500,H$96)/SUMIFS('Asset Value'!$D$4:$D$500,'Asset Value'!$C$4:$C$500,$A98,'Asset Value'!$B$4:$B$500,H$96),0) -> 25994.036 | I98: =IFERROR(SUMIFS('Asset Value'!$F$4:$F$500,'Asset Value'!$C$4:$C$500,$A98,'Asset Value'!$B$4:$B$500,I$96)/SUMIFS('Asset Value'!$D$4:$D$500,'Asset Value'!$C$4:$C$500,$A98,'Asset Value'!$B$4:$B$500,I$96),0) -> 27157.768 | J98: =_xlfn.MINIFS($B$86:$I$86,$B98:$I98,">0") -> 2008 | K98: =_xlfn.MAXIFS($B$86:$I$86,$B98:$I98,">0") -> 2015 | L98: =INDEX($B98:$I98,MATCH(J98,$B$86:$I$86,0)) -> 11876.608 | M98: =INDEX($B98:$I98,MATCH(K98,$B$86:$I$86,0)) -> 27157.768 | N98: =M98/L98-1 -> 1.2866603 | O98: =IF(K98>J98,(M98/L98)^(1/(K98-J98))-1,"") -> 0.12541972
A99: Fazenda Planeste | B99: =IFERROR(SUMIFS('Asset Value'!$F$4:$F$500,'Asset Value'!$C$4:$C$500,$A99,'Asset Value'!$B$4:$B$500,B$96)/SUMIFS('Asset Value'!$D$4:$D$500,'Asset Value'!$C$4:$C$500,$A99,'Asset Value'!$B$4:$B$500,B$96),0) -> 5857.8002 | C99: =IFERROR(SUMIFS('Asset Value'!$F$4:$F$500,'Asset Value'!$C$4:$C$500,$A99,'Asset Value'!$B$4:$B$500,C$96)/SUMIFS('Asset Value'!$D$4:$D$500,'Asset Value'!$C$4:$C$500,$A99,'Asset Value'!$B$4:$B$500,C$96),0) -> 6465.8195 | D99: =IFERROR(SUMIFS('Asset Value'!$F$4:$F$500,'Asset Value'!$C$4:$C$500,$A99,'Asset Value'!$B$4:$B$500,D$96)/SUMIFS('Asset Value'!$D$4:$D$500,'Asset Value'!$C$4:$C$500,$A99,'Asset Value'!$B$4:$B$500,D$96),0) -> 6239.0837 | E99: =IFERROR(SUMIFS('Asset Value'!$F$4:$F$500,'Asset Value'!$C$4:$C$500,$A99,'Asset Value'!$B$4:$B$500,E$96)/SUMIFS('Asset Value'!$D$4:$D$500,'Asset Value'!$C$4:$C$500,$A99,'Asset Value'!$B$4:$B$500,E$96),0) -> 7590.7316 | F99: =IFERROR(SUMIFS('Asset Value'!$F$4:$F$500,'Asset Value'!$C$4:$C$500,$A99,'Asset Value'!$B$4:$B$500,F$96)/SUMIFS('Asset Value'!$D$4:$D$500,'Asset Value'!$C$4:$C$500,$A99,'Asset Value'!$B$4:$B$500,F$96),0) -> 8466.0665 | G99: =IFERROR(SUMIFS('Asset Value'!$F$4:$F$500,'Asset Value'!$C$4:$C$500,$A99,'Asset Value'!$B$4:$B$500,G$96)/SUMIFS('Asset Value'!$D$4:$D$500,'Asset Value'!$C$4:$C$500,$A99,'Asset Value'!$B$4:$B$500,G$96),0) -> 9440.6431 | H99: =IFERROR(SUMIFS('Asset Value'!$F$4:$F$500,'Asset Value'!$C$4:$C$500,$A99,'Asset Value'!$B$4:$B$500,H$96)/SUMIFS('Asset Value'!$D$4:$D$500,'Asset Value'!$C$4:$C$500,$A99,'Asset Value'!$B$4:$B$500,H$96),0) -> 9846.6881 | I99: =IFERROR(SUMIFS('Asset Value'!$F$4:$F$500,'Asset Value'!$C$4:$C$500,$A99,'Asset Value'!$B$4:$B$500,I$96)/SUMIFS('Asset Value'!$D$4:$D$500,'Asset Value'!$C$4:$C$500,$A99,'Asset Value'!$B$4:$B$500,I$96),0) -> 10055.303 | J99: =_xlfn.MINIFS($B$86:$I$86,$B99:$I99,">0") -> 2008 | K99: =_xlfn.MAXIFS($B$86:$I$86,$B99:$I99,">0") -> 2015 | L99: =INDEX($B99:$I99,MATCH(J99,$B$86:$I$86,0)) -> 5857.8002 | M99: =INDEX($B99:$I99,MATCH(K99,$B$86:$I$86,0)) -> 10055.303 | N99: =M99/L99-1 -> 0.71656642 | O99: =IF(K99>J99,(M99/L99)^(1/(K99-J99))-1,"") -> 0.080246691
A100: Fazenda Panorama | B100: =IFERROR(SUMIFS('Asset Value'!$F$4:$F$500,'Asset Value'!$C$4:$C$500,$A100,'Asset Value'!$B$4:$B$500,B$96)/SUMIFS('Asset Value'!$D$4:$D$500,'Asset Value'!$C$4:$C$500,$A100,'Asset Value'!$B$4:$B$500,B$96),0) -> 8144.2516 | C100: =IFERROR(SUMIFS('Asset Value'!$F$4:$F$500,'Asset Value'!$C$4:$C$500,$A100,'Asset Value'!$B$4:$B$500,C$96)/SUMIFS('Asset Value'!$D$4:$D$500,'Asset Value'!$C$4:$C$500,$A100,'Asset Value'!$B$4:$B$500,C$96),0) -> 9366.5944 | D100: =IFERROR(SUMIFS('Asset Value'!$F$4:$F$500,'Asset Value'!$C$4:$C$500,$A100,'Asset Value'!$B$4:$B$500,D$96)/SUMIFS('Asset Value'!$D$4:$D$500,'Asset Value'!$C$4:$C$500,$A100,'Asset Value'!$B$4:$B$500,D$96),0) -> 9910.3528 | E100: =IFERROR(SUMIFS('Asset Value'!$F$4:$F$500,'Asset Value'!$C$4:$C$500,$A100,'Asset Value'!$B$4:$B$500,E$96)/SUMIFS('Asset Value'!$D$4:$D$500,'Asset Value'!$C$4:$C$500,$A100,'Asset Value'!$B$4:$B$500,E$96),0) -> 11301.032 | F100: =IFERROR(SUMIFS('Asset Value'!$F$4:$F$500,'Asset Value'!$C$4:$C$500,$A100,'Asset Value'!$B$4:$B$500,F$96)/SUMIFS('Asset Value'!$D$4:$D$500,'Asset Value'!$C$4:$C$500,$A100,'Asset Value'!$B$4:$B$500,F$96),0) -> 12899.176 | G100: =IFERROR(SUMIFS('Asset Value'!$F$4:$F$500,'Asset Value'!$C$4:$C$500,$A100,'Asset Value'!$B$4:$B$500,G$96)/SUMIFS('Asset Value'!$D$4:$D$500,'Asset Value'!$C$4:$C$500,$A100,'Asset Value'!$B$4:$B$500,G$96),0) -> 14021.207 | H100: =IFERROR(SUMIFS('Asset Value'!$F$4:$F$500,'Asset Value'!$C$4:$C$500,$A100,'Asset Value'!$B$4:$B$500,H$96)/SUMIFS('Asset Value'!$D$4:$D$500,'Asset Value'!$C$4:$C$500,$A100,'Asset Value'!$B$4:$B$500,H$96),0) -> 15071.332 | I100: =IFERROR(SUMIFS('Asset Value'!$F$4:$F$500,'Asset Value'!$C$4:$C$500,$A100,'Asset Value'!$B$4:$B$500,I$96)/SUMIFS('Asset Value'!$D$4:$D$500,'Asset Value'!$C$4:$C$500,$A100,'Asset Value'!$B$4:$B$500,I$96),0) -> 16042.992 | J100: =_xlfn.MINIFS($B$86:$I$86,$B100:$I100,">0") -> 2008 | K100: =_xlfn.MAXIFS($B$86:$I$86,$B100:$I100,">0") -> 2015 | L100: =INDEX($B100:$I100,MATCH(J100,$B$86:$I$86,0)) -> 8144.2516 | M100: =INDEX($B100:$I100,MATCH(K100,$B$86:$I$86,0)) -> 16042.992 | N100: =M100/L100-1 -> 0.96985467 | O100: =IF(K100>J100,(M100/L100)^(1/(K100-J100))-1,"") -> 0.10169664
A101: Fazenda Piratini | B101: =IFERROR(SUMIFS('Asset Value'!$F$4:$F$500,'Asset Value'!$C$4:$C$500,$A101,'Asset Value'!$B$4:$B$500,B$96)/SUMIFS('Asset Value'!$D$4:$D$500,'Asset Value'!$C$4:$C$500,$A101,'Asset Value'!$B$4:$B$500,B$96),0) -> 2356.6115 | C101: =IFERROR(SUMIFS('Asset Value'!$F$4:$F$500,'Asset Value'!$C$4:$C$500,$A101,'Asset Value'!$B$4:$B$500,C$96)/SUMIFS('Asset Value'!$D$4:$D$500,'Asset Value'!$C$4:$C$500,$A101,'Asset Value'!$B$4:$B$500,C$96),0) -> 3793.2965 | D101: =IFERROR(SUMIFS('Asset Value'!$F$4:$F$500,'Asset Value'!$C$4:$C$500,$A101,'Asset Value'!$B$4:$B$500,D$96)/SUMIFS('Asset Value'!$D$4:$D$500,'Asset Value'!$C$4:$C$500,$A101,'Asset Value'!$B$4:$B$500,D$96),0) -> 3226.5825 | E101: =IFERROR(SUMIFS('Asset Value'!$F$4:$F$500,'Asset Value'!$C$4:$C$500,$A101,'Asset Value'!$B$4:$B$500,E$96)/SUMIFS('Asset Value'!$D$4:$D$500,'Asset Value'!$C$4:$C$500,$A101,'Asset Value'!$B$4:$B$500,E$96),0) -> 4615.2633 | F101: =IFERROR(SUMIFS('Asset Value'!$F$4:$F$500,'Asset Value'!$C$4:$C$500,$A101,'Asset Value'!$B$4:$B$500,F$96)/SUMIFS('Asset Value'!$D$4:$D$500,'Asset Value'!$C$4:$C$500,$A101,'Asset Value'!$B$4:$B$500,F$96),0) -> 5268.5072 | G101: =IFERROR(SUMIFS('Asset Value'!$F$4:$F$500,'Asset Value'!$C$4:$C$500,$A101,'Asset Value'!$B$4:$B$500,G$96)/SUMIFS('Asset Value'!$D$4:$D$500,'Asset Value'!$C$4:$C$500,$A101,'Asset Value'!$B$4:$B$500,G$96),0) -> 6957.3654 | H101: =IFERROR(SUMIFS('Asset Value'!$F$4:$F$500,'Asset Value'!$C$4:$C$500,$A101,'Asset Value'!$B$4:$B$500,H$96)/SUMIFS('Asset Value'!$D$4:$D$500,'Asset Value'!$C$4:$C$500,$A101,'Asset Value'!$B$4:$B$500,H$96),0) -> 7817.393 | I101: =IFERROR(SUMIFS('Asset Value'!$F$4:$F$500,'Asset Value'!$C$4:$C$500,$A101,'Asset Value'!$B$4:$B$500,I$96)/SUMIFS('Asset Value'!$D$4:$D$500,'Asset Value'!$C$4:$C$500,$A101,'Asset Value'!$B$4:$B$500,I$96),0) -> 8789.2412 | J101: =_xlfn.MINIFS($B$86:$I$86,$B101:$I101,">0") -> 2008 | K101: =_xlfn.MAXIFS($B$86:$I$86,$B101:$I101,">0") -> 2015 | L101: =INDEX($B101:$I101,MATCH(J101,$B$86:$I$86,0)) -> 2356.6115 | M101: =INDEX($B101:$I101,MATCH(K101,$B$86:$I$86,0)) -> 8789.2412 | N101: =M101/L101-1 -> 2.7296098 | O101: =IF(K101>J101,(M101/L101)^(1/(K101-J101))-1,"") -> 0.20688586
A102: Fazenda Palmares | B102: =IFERROR(SUMIFS('Asset Value'!$F$4:$F$500,'Asset Value'!$C$4:$C$500,$A102,'Asset Value'!$B$4:$B$500,B$96)/SUMIFS('Asset Value'!$D$4:$D$500,'Asset Value'!$C$4:$C$500,$A102,'Asset Value'!$B$4:$B$500,B$96),0) -> 0 | C102: =IFERROR(SUMIFS('Asset Value'!$F$4:$F$500,'Asset Value'!$C$4:$C$500,$A102,'Asset Value'!$B$4:$B$500,C$96)/SUMIFS('Asset Value'!$D$4:$D$500,'Asset Value'!$C$4:$C$500,$A102,'Asset Value'!$B$4:$B$500,C$96),0) -> 4314.3939 | D102: =IFERROR(SUMIFS('Asset Value'!$F$4:$F$500,'Asset Value'!$C$4:$C$500,$A102,'Asset Value'!$B$4:$B$500,D$96)/SUMIFS('Asset Value'!$D$4:$D$500,'Asset Value'!$C$4:$C$500,$A102,'Asset Value'!$B$4:$B$500,D$96),0) -> 4078.901 | E102: =IFERROR(SUMIFS('Asset Value'!$F$4:$F$500,'Asset Value'!$C$4:$C$500,$A102,'Asset Value'!$B$4:$B$500,E$96)/SUMIFS('Asset Value'!$D$4:$D$500,'Asset Value'!$C$4:$C$500,$A102,'Asset Value'!$B$4:$B$500,E$96),0) -> 4955.747 | F102: =IFERROR(SUMIFS('Asset Value'!$F$4:$F$500,'Asset Value'!$C$4:$C$500,$A102,'Asset Value'!$B$4:$B$500,F$96)/SUMIFS('Asset Value'!$D$4:$D$500,'Asset Value'!$C$4:$C$500,$A102,'Asset Value'!$B$4:$B$500,F$96),0) -> 6033.7503 | G102: =IFERROR(SUMIFS('Asset Value'!$F$4:$F$500,'Asset Value'!$C$4:$C$500,$A102,'Asset Value'!$B$4:$B$500,G$96)/SUMIFS('Asset Value'!$D$4:$D$500,'Asset Value'!$C$4:$C$500,$A102,'Asset Value'!$B$4:$B$500,G$96),0) -> 10218.61 | H102: =IFERROR(SUMIFS('Asset Value'!$F$4:$F$500,'Asset Value'!$C$4:$C$500,$A102,'Asset Value'!$B$4:$B$500,H$96)/SUMIFS('Asset Value'!$D$4:$D$500,'Asset Value'!$C$4:$C$500,$A102,'Asset Value'!$B$4:$B$500,H$96),0) -> 11324.592 | I102: =IFERROR(SUMIFS('Asset Value'!$F$4:$F$500,'Asset Value'!$C$4:$C$500,$A102,'Asset Value'!$B$4:$B$500,I$96)/SUMIFS('Asset Value'!$D$4:$D$500,'Asset Value'!$C$4:$C$500,$A102,'Asset Value'!$B$4:$B$500,I$96),0) -> 11603.884 | J102: =_xlfn.MINIFS($B$86:$I$86,$B102:$I102,">0") -> 2009 | K102: =_xlfn.MAXIFS($B$86:$I$86,$B102:$I102,">0") -> 2015 | L102: =INDEX($B102:$I102,MATCH(J102,$B$86:$I$86,0)) -> 4314.3939 | M102: =INDEX($B102:$I102,MATCH(K102,$B$86:$I$86,0)) -> 11603.884 | N102: =M102/L102-1 -> 1.6895746 | O102: =IF(K102>J102,(M102/L102)^(1/(K102-J102))-1,"") -> 0.17927185
A103: Fazenda Parnaíba | B103: =IFERROR(SUMIFS('Asset Value'!$F$4:$F$500,'Asset Value'!$C$4:$C$500,$A103,'Asset Value'!$B$4:$B$500,B$96)/SUMIFS('Asset Value'!$D$4:$D$500,'Asset Value'!$C$4:$C$500,$A103,'Asset Value'!$B$4:$B$500,B$96),0) -> 6005.9807 | C103: =IFERROR(SUMIFS('Asset Value'!$F$4:$F$500,'Asset Value'!$C$4:$C$500,$A103,'Asset Value'!$B$4:$B$500,C$96)/SUMIFS('Asset Value'!$D$4:$D$500,'Asset Value'!$C$4:$C$500,$A103,'Asset Value'!$B$4:$B$500,C$96),0) -> 6134.9784 | D103: =IFERROR(SUMIFS('Asset Value'!$F$4:$F$500,'Asset Value'!$C$4:$C$500,$A103,'Asset Value'!$B$4:$B$500,D$96)/SUMIFS('Asset Value'!$D$4:$D$500,'Asset Value'!$C$4:$C$500,$A103,'Asset Value'!$B$4:$B$500,D$96),0) -> 5924.29 | E103: =IFERROR(SUMIFS('Asset Value'!$F$4:$F$500,'Asset Value'!$C$4:$C$500,$A103,'Asset Value'!$B$4:$B$500,E$96)/SUMIFS('Asset Value'!$D$4:$D$500,'Asset Value'!$C$4:$C$500,$A103,'Asset Value'!$B$4:$B$500,E$96),0) -> 6597.7945 | F103: =IFERROR(SUMIFS('Asset Value'!$F$4:$F$500,'Asset Value'!$C$4:$C$500,$A103,'Asset Value'!$B$4:$B$500,F$96)/SUMIFS('Asset Value'!$D$4:$D$500,'Asset Value'!$C$4:$C$500,$A103,'Asset Value'!$B$4:$B$500,F$96),0) -> 7770.795 | G103: =IFERROR(SUMIFS('Asset Value'!$F$4:$F$500,'Asset Value'!$C$4:$C$500,$A103,'Asset Value'!$B$4:$B$500,G$96)/SUMIFS('Asset Value'!$D$4:$D$500,'Asset Value'!$C$4:$C$500,$A103,'Asset Value'!$B$4:$B$500,G$96),0) -> 9304.7718 | H103: =IFERROR(SUMIFS('Asset Value'!$F$4:$F$500,'Asset Value'!$C$4:$C$500,$A103,'Asset Value'!$B$4:$B$500,H$96)/SUMIFS('Asset Value'!$D$4:$D$500,'Asset Value'!$C$4:$C$500,$A103,'Asset Value'!$B$4:$B$500,H$96),0) -> 8305.1699 | I103: =IFERROR(SUMIFS('Asset Value'!$F$4:$F$500,'Asset Value'!$C$4:$C$500,$A103,'Asset Value'!$B$4:$B$500,I$96)/SUMIFS('Asset Value'!$D$4:$D$500,'Asset Value'!$C$4:$C$500,$A103,'Asset Value'!$B$4:$B$500,I$96),0) -> 8728.3164 | J103: =_xlfn.MINIFS($B$86:$I$86,$B103:$I103,">0") -> 2008 | K103: =_xlfn.MAXIFS($B$86:$I$86,$B103:$I103,">0") -> 2015 | L103: =INDEX($B103:$I103,MATCH(J103,$B$86:$I$86,0)) -> 6005.9807 | M103: =INDEX($B103:$I103,MATCH(K103,$B$86:$I$86,0)) -> 8728.3164 | N103: =M103/L103-1 -> 0.4532708 | O103: =IF(K103>J103,(M103/L103)^(1/(K103-J103))-1,"") -> 0.054854024
A104: Fazenda Paiaguás | B104: =IFERROR(SUMIFS('Asset Value'!$F$4:$F$500,'Asset Value'!$C$4:$C$500,$A104,'Asset Value'!$B$4:$B$500,B$96)/SUMIFS('Asset Value'!$D$4:$D$500,'Asset Value'!$C$4:$C$500,$A104,'Asset Value'!$B$4:$B$500,B$96),0) -> 8334.5394 | C104: =IFERROR(SUMIFS('Asset Value'!$F$4:$F$500,'Asset Value'!$C$4:$C$500,$A104,'Asset Value'!$B$4:$B$500,C$96)/SUMIFS('Asset Value'!$D$4:$D$500,'Asset Value'!$C$4:$C$500,$A104,'Asset Value'!$B$4:$B$500,C$96),0) -> 10094.451 | D104: =IFERROR(SUMIFS('Asset Value'!$F$4:$F$500,'Asset Value'!$C$4:$C$500,$A104,'Asset Value'!$B$4:$B$500,D$96)/SUMIFS('Asset Value'!$D$4:$D$500,'Asset Value'!$C$4:$C$500,$A104,'Asset Value'!$B$4:$B$500,D$96),0) -> 9290.8558 | E104: =IFERROR(SUMIFS('Asset Value'!$F$4:$F$500,'Asset Value'!$C$4:$C$500,$A104,'Asset Value'!$B$4:$B$500,E$96)/SUMIFS('Asset Value'!$D$4:$D$500,'Asset Value'!$C$4:$C$500,$A104,'Asset Value'!$B$4:$B$500,E$96),0) -> 10647.446 | F104: =IFERROR(SUMIFS('Asset Value'!$F$4:$F$500,'Asset Value'!$C$4:$C$500,$A104,'Asset Value'!$B$4:$B$500,F$96)/SUMIFS('Asset Value'!$D$4:$D$500,'Asset Value'!$C$4:$C$500,$A104,'Asset Value'!$B$4:$B$500,F$96),0) -> 12701.285 | G104: =IFERROR(SUMIFS('Asset Value'!$F$4:$F$500,'Asset Value'!$C$4:$C$500,$A104,'Asset Value'!$B$4:$B$500,G$96)/SUMIFS('Asset Value'!$D$4:$D$500,'Asset Value'!$C$4:$C$500,$A104,'Asset Value'!$B$4:$B$500,G$96),0) -> 13052.059 | H104: =IFERROR(SUMIFS('Asset Value'!$F$4:$F$500,'Asset Value'!$C$4:$C$500,$A104,'Asset Value'!$B$4:$B$500,H$96)/SUMIFS('Asset Value'!$D$4:$D$500,'Asset Value'!$C$4:$C$500,$A104,'Asset Value'!$B$4:$B$500,H$96),0) -> 16016.872 | I104: =IFERROR(SUMIFS('Asset Value'!$F$4:$F$500,'Asset Value'!$C$4:$C$500,$A104,'Asset Value'!$B$4:$B$500,I$96)/SUMIFS('Asset Value'!$D$4:$D$500,'Asset Value'!$C$4:$C$500,$A104,'Asset Value'!$B$4:$B$500,I$96),0) -> 17172.944 | J104: =_xlfn.MINIFS($B$86:$I$86,$B104:$I104,">0") -> 2008 | K104: =_xlfn.MAXIFS($B$86:$I$86,$B104:$I104,">0") -> 2015 | L104: =INDEX($B104:$I104,MATCH(J104,$B$86:$I$86,0)) -> 8334.5394 | M104: =INDEX($B104:$I104,MATCH(K104,$B$86:$I$86,0)) -> 17172.944 | N104: =M104/L104-1 -> 1.0604551 | O104: =IF(K104>J104,(M104/L104)^(1/(K104-J104))-1,"") -> 0.10879659
A105: Fazenda Pejuçara | B105: =IFERROR(SUMIFS('Asset Value'!$F$4:$F$500,'Asset Value'!$C$4:$C$500,$A105,'Asset Value'!$B$4:$B$500,B$96)/SUMIFS('Asset Value'!$D$4:$D$500,'Asset Value'!$C$4:$C$500,$A105,'Asset Value'!$B$4:$B$500,B$96),0) -> 0 | C105: =IFERROR(SUMIFS('Asset Value'!$F$4:$F$500,'Asset Value'!$C$4:$C$500,$A105,'Asset Value'!$B$4:$B$500,C$96)/SUMIFS('Asset Value'!$D$4:$D$500,'Asset Value'!$C$4:$C$500,$A105,'Asset Value'!$B$4:$B$500,C$96),0) -> 0 | D105: =IFERROR(SUMIFS('Asset Value'!$F$4:$F$500,'Asset Value'!$C$4:$C$500,$A105,'Asset Value'!$B$4:$B$500,D$96)/SUMIFS('Asset Value'!$D$4:$D$500,'Asset Value'!$C$4:$C$500,$A105,'Asset Value'!$B$4:$B$500,D$96),0) -> 0 | E105: =IFERROR(SUMIFS('Asset Value'!$F$4:$F$500,'Asset Value'!$C$4:$C$500,$A105,'Asset Value'!$B$4:$B$500,E$96)/SUMIFS('Asset Value'!$D$4:$D$500,'Asset Value'!$C$4:$C$500,$A105,'Asset Value'!$B$4:$B$500,E$96),0) -> 0 | F105: =IFERROR(SUMIFS('Asset Value'!$F$4:$F$500,'Asset Value'!$C$4:$C$500,$A105,'Asset Value'!$B$4:$B$500,F$96)/SUMIFS('Asset Value'!$D$4:$D$500,'Asset Value'!$C$4:$C$500,$A105,'Asset Value'!$B$4:$B$500,F$96),0) -> 12311.335 | G105: =IFERROR(SUMIFS('Asset Value'!$F$4:$F$500,'Asset Value'!$C$4:$C$500,$A105,'Asset Value'!$B$4:$B$500,G$96)/SUMIFS('Asset Value'!$D$4:$D$500,'Asset Value'!$C$4:$C$500,$A105,'Asset Value'!$B$4:$B$500,G$96),0) -> 12615.271 | H105: =IFERROR(SUMIFS('Asset Value'!$F$4:$F$500,'Asset Value'!$C$4:$C$500,$A105,'Asset Value'!$B$4:$B$500,H$96)/SUMIFS('Asset Value'!$D$4:$D$500,'Asset Value'!$C$4:$C$500,$A105,'Asset Value'!$B$4:$B$500,H$96),0) -> 0 | I105: =IFERROR(SUMIFS('Asset Value'!$F$4:$F$500,'Asset Value'!$C$4:$C$500,$A105,'Asset Value'!$B$4:$B$500,I$96)/SUMIFS('Asset Value'!$D$4:$D$500,'Asset Value'!$C$4:$C$500,$A105,'Asset Value'!$B$4:$B$500,I$96),0) -> 0 | J105: =_xlfn.MINIFS($B$86:$I$86,$B105:$I105,">0") -> 2012 | K105: =_xlfn.MAXIFS($B$86:$I$86,$B105:$I105,">0") -> 2013 | L105: =INDEX($B105:$I105,MATCH(J105,$B$86:$I$86,0)) -> 12311.335 | M105: =INDEX($B105:$I105,MATCH(K105,$B$86:$I$86,0)) -> 12615.271 | N105: =M105/L105-1 -> 0.0246875 | O105: =IF(K105>J105,(M105/L105)^(1/(K105-J105))-1,"") -> 0.0246875
A106: Fazenda Parceiro | B106: =IFERROR(SUMIFS('Asset Value'!$F$4:$F$500,'Asset Value'!$C$4:$C$500,$A106,'Asset Value'!$B$4:$B$500,B$96)/SUMIFS('Asset Value'!$D$4:$D$500,'Asset Value'!$C$4:$C$500,$A106,'Asset Value'!$B$4:$B$500,B$96),0) -> 0 | C106: =IFERROR(SUMIFS('Asset Value'!$F$4:$F$500,'Asset Value'!$C$4:$C$500,$A106,'Asset Value'!$B$4:$B$500,C$96)/SUMIFS('Asset Value'!$D$4:$D$500,'Asset Value'!$C$4:$C$500,$A106,'Asset Value'!$B$4:$B$500,C$96),0) -> 0 | D106: =IFERROR(SUMIFS('Asset Value'!$F$4:$F$500,'Asset Value'!$C$4:$C$500,$A106,'Asset Value'!$B$4:$B$500,D$96)/SUMIFS('Asset Value'!$D$4:$D$500,'Asset Value'!$C$4:$C$500,$A106,'Asset Value'!$B$4:$B$500,D$96),0) -> 0 | E106: =IFERROR(SUMIFS('Asset Value'!$F$4:$F$500,'Asset Value'!$C$4:$C$500,$A106,'Asset Value'!$B$4:$B$500,E$96)/SUMIFS('Asset Value'!$D$4:$D$500,'Asset Value'!$C$4:$C$500,$A106,'Asset Value'!$B$4:$B$500,E$96),0) -> 0 | F106: =IFERROR(SUMIFS('Asset Value'!$F$4:$F$500,'Asset Value'!$C$4:$C$500,$A106,'Asset Value'!$B$4:$B$500,F$96)/SUMIFS('Asset Value'!$D$4:$D$500,'Asset Value'!$C$4:$C$500,$A106,'Asset Value'!$B$4:$B$500,F$96),0) -> 3485.0683 | G106: =IFERROR(SUMIFS('Asset Value'!$F$4:$F$500,'Asset Value'!$C$4:$C$500,$A106,'Asset Value'!$B$4:$B$500,G$96)/SUMIFS('Asset Value'!$D$4:$D$500,'Asset Value'!$C$4:$C$500,$A106,'Asset Value'!$B$4:$B$500,G$96),0) -> 5333.8093 | H106: =IFERROR(SUMIFS('Asset Value'!$F$4:$F$500,'Asset Value'!$C$4:$C$500,$A106,'Asset Value'!$B$4:$B$500,H$96)/SUMIFS('Asset Value'!$D$4:$D$500,'Asset Value'!$C$4:$C$500,$A106,'Asset Value'!$B$4:$B$500,H$96),0) -> 6182.391 | I106: =IFERROR(SUMIFS('Asset Value'!$F$4:$F$500,'Asset Value'!$C$4:$C$500,$A106,'Asset Value'!$B$4:$B$500,I$96)/SUMIFS('Asset Value'!$D$4:$D$500,'Asset Value'!$C$4:$C$500,$A106,'Asset Value'!$B$4:$B$500,I$96),0) -> 6409.2843 | J106: =_xlfn.MINIFS($B$86:$I$86,$B106:$I106,">0") -> 2012 | K106: =_xlfn.MAXIFS($B$86:$I$86,$B106:$I106,">0") -> 2015 | L106: =INDEX($B106:$I106,MATCH(J106,$B$86:$I$86,0)) -> 3485.0683 | M106: =INDEX($B106:$I106,MATCH(K106,$B$86:$I$86,0)) -> 6409.2843 | N106: =M106/L106-1 -> 0.83906995 | O106: =IF(K106>J106,(M106/L106)^(1/(K106-J106))-1,"") -> 0.22517864
A107: Fazenda Perdizes | B107: =IFERROR(SUMIFS('Asset Value'!$F$4:$F$500,'Asset Value'!$C$4:$C$500,$A107,'Asset Value'!$B$4:$B$500,B$96)/SUMIFS('Asset Value'!$D$4:$D$500,'Asset Value'!$C$4:$C$500,$A107,'Asset Value'!$B$4:$B$500,B$96),0) -> 0 | C107: =IFERROR(SUMIFS('Asset Value'!$F$4:$F$500,'Asset Value'!$C$4:$C$500,$A107,'Asset Value'!$B$4:$B$500,C$96)/SUMIFS('Asset Value'!$D$4:$D$500,'Asset Value'!$C$4:$C$500,$A107,'Asset Value'!$B$4:$B$500,C$96),0) -> 0 | D107: =IFERROR(SUMIFS('Asset Value'!$F$4:$F$500,'Asset Value'!$C$4:$C$500,$A107,'Asset Value'!$B$4:$B$500,D$96)/SUMIFS('Asset Value'!$D$4:$D$500,'Asset Value'!$C$4:$C$500,$A107,'Asset Value'!$B$4:$B$500,D$96),0) -> 0 | E107: =IFERROR(SUMIFS('Asset Value'!$F$4:$F$500,'Asset Value'!$C$4:$C$500,$A107,'Asset Value'!$B$4:$B$500,E$96)/SUMIFS('Asset Value'!$D$4:$D$500,'Asset Value'!$C$4:$C$500,$A107,'Asset Value'!$B$4:$B$500,E$96),0) -> 0 | F107: =IFERROR(SUMIFS('Asset Value'!$F$4:$F$500,'Asset Value'!$C$4:$C$500,$A107,'Asset Value'!$B$4:$B$500,F$96)/SUMIFS('Asset Value'!$D$4:$D$500,'Asset Value'!$C$4:$C$500,$A107,'Asset Value'!$B$4:$B$500,F$96),0) -> 2919.3397 | G107: =IFERROR(SUMIFS('Asset Value'!$F$4:$F$500,'Asset Value'!$C$4:$C$500,$A107,'Asset Value'!$B$4:$B$500,G$96)/SUMIFS('Asset Value'!$D$4:$D$500,'Asset Value'!$C$4:$C$500,$A107,'Asset Value'!$B$4:$B$500,G$96),0) -> 5747.1651 | H107: =IFERROR(SUMIFS('Asset Value'!$F$4:$F$500,'Asset Value'!$C$4:$C$500,$A107,'Asset Value'!$B$4:$B$500,H$96)/SUMIFS('Asset Value'!$D$4:$D$500,'Asset Value'!$C$4:$C$500,$A107,'Asset Value'!$B$4:$B$500,H$96),0) -> 5923.3808 | I107: =IFERROR(SUMIFS('Asset Value'!$F$4:$F$500,'Asset Value'!$C$4:$C$500,$A107,'Asset Value'!$B$4:$B$500,I$96)/SUMIFS('Asset Value'!$D$4:$D$500,'Asset Value'!$C$4:$C$500,$A107,'Asset Value'!$B$4:$B$500,I$96),0) -> 6069.6328 | J107: =_xlfn.MINIFS($B$86:$I$86,$B107:$I107,">0") -> 2012 | K107: =_xlfn.MAXIFS($B$86:$I$86,$B107:$I107,">0") -> 2015 | L107: =INDEX($B107:$I107,MATCH(J107,$B$86:$I$86,0)) -> 2919.3397 | M107: =INDEX($B107:$I107,MATCH(K107,$B$86:$I$86,0)) -> 6069.6328 | N107: =M107/L107-1 -> 1.0791115 | O107: =IF(K107>J107,(M107/L107)^(1/(K107-J107))-1,"") -> 0.27631907
A108: Fazenda Planorte | B108: =IFERROR(SUMIFS('Asset Value'!$F$4:$F$500,'Asset Value'!$C$4:$C$500,$A108,'Asset Value'!$B$4:$B$500,B$96)/SUMIFS('Asset Value'!$D$4:$D$500,'Asset Value'!$C$4:$C$500,$A108,'Asset Value'!$B$4:$B$500,B$96),0) -> 8243.7875 | C108: =IFERROR(SUMIFS('Asset Value'!$F$4:$F$500,'Asset Value'!$C$4:$C$500,$A108,'Asset Value'!$B$4:$B$500,C$96)/SUMIFS('Asset Value'!$D$4:$D$500,'Asset Value'!$C$4:$C$500,$A108,'Asset Value'!$B$4:$B$500,C$96),0) -> 9791.9644 | D108: =IFERROR(SUMIFS('Asset Value'!$F$4:$F$500,'Asset Value'!$C$4:$C$500,$A108,'Asset Value'!$B$4:$B$500,D$96)/SUMIFS('Asset Value'!$D$4:$D$500,'Asset Value'!$C$4:$C$500,$A108,'Asset Value'!$B$4:$B$500,D$96),0) -> 8407.9351 | E108: =IFERROR(SUMIFS('Asset Value'!$F$4:$F$500,'Asset Value'!$C$4:$C$500,$A108,'Asset Value'!$B$4:$B$500,E$96)/SUMIFS('Asset Value'!$D$4:$D$500,'Asset Value'!$C$4:$C$500,$A108,'Asset Value'!$B$4:$B$500,E$96),0) -> 9216.5763 | F108: =IFERROR(SUMIFS('Asset Value'!$F$4:$F$500,'Asset Value'!$C$4:$C$500,$A108,'Asset Value'!$B$4:$B$500,F$96)/SUMIFS('Asset Value'!$D$4:$D$500,'Asset Value'!$C$4:$C$500,$A108,'Asset Value'!$B$4:$B$500,F$96),0) -> 10718.278 | G108: =IFERROR(SUMIFS('Asset Value'!$F$4:$F$500,'Asset Value'!$C$4:$C$500,$A108,'Asset Value'!$B$4:$B$500,G$96)/SUMIFS('Asset Value'!$D$4:$D$500,'Asset Value'!$C$4:$C$500,$A108,'Asset Value'!$B$4:$B$500,G$96),0) -> 10794.147 | H108: =IFERROR(SUMIFS('Asset Value'!$F$4:$F$500,'Asset Value'!$C$4:$C$500,$A108,'Asset Value'!$B$4:$B$500,H$96)/SUMIFS('Asset Value'!$D$4:$D$500,'Asset Value'!$C$4:$C$500,$A108,'Asset Value'!$B$4:$B$500,H$96),0) -> 12960.099 | I108: =IFERROR(SUMIFS('Asset Value'!$F$4:$F$500,'Asset Value'!$C$4:$C$500,$A108,'Asset Value'!$B$4:$B$500,I$96)/SUMIFS('Asset Value'!$D$4:$D$500,'Asset Value'!$C$4:$C$500,$A108,'Asset Value'!$B$4:$B$500,I$96),0) -> 13476.258 | J108: =_xlfn.MINIFS($B$86:$I$86,$B108:$I108,">0") -> 2008 | K108: =_xlfn.MAXIFS($B$86:$I$86,$B108:$I108,">0") -> 2015 | L108: =INDEX($B108:$I108,MATCH(J108,$B$86:$I$86,0)) -> 8243.7875 | M108: =INDEX($B108:$I108,MATCH(K108,$B$86:$I$86,0)) -> 13476.258 | N108: =M108/L108-1 -> 0.63471675 | O108: =IF(K108>J108,(M108/L108)^(1/(K108-J108))-1,"") -> 0.072733362
... A111: Fazenda Palmeira | B111: =IFERROR(SUMIFS('Asset Value'!$F$4:$F$500,'Asset Value'!$C$4:$C$500,$A111,'Asset Value'!$B$4:$B$500,B$96)/SUMIFS('Asset Value'!$D$4:$D$500,'Asset Value'!$C$4:$C$500,$A111,'Asset Value'!$B$4:$B$500,B$96),0) -> 1371.3827 | C111: =IFERROR(SUMIFS('Asset Value'!$F$4:$F$500,'Asset Value'!$C$4:$C$500,$A111,'Asset Value'!$B$4:$B$500,C$96)/SUMIFS('Asset Value'!$D$4:$D$500,'Asset Value'!$C$4:$C$500,$A111,'Asset Value'!$B$4:$B$500,C$96),0) -> 1688.1641 | D111: =IFERROR(SUMIFS('Asset Value'!$F$4:$F$500,'Asset Value'!$C$4:$C$500,$A111,'Asset Value'!$B$4:$B$500,D$96)/SUMIFS('Asset Value'!$D$4:$D$500,'Asset Value'!$C$4:$C$500,$A111,'Asset Value'!$B$4:$B$500,D$96),0) -> 1699.1453 | E111: =IFERROR(SUMIFS('Asset Value'!$F$4:$F$500,'Asset Value'!$C$4:$C$500,$A111,'Asset Value'!$B$4:$B$500,E$96)/SUMIFS('Asset Value'!$D$4:$D$500,'Asset Value'!$C$4:$C$500,$A111,'Asset Value'!$B$4:$B$500,E$96),0) -> 0 | F111: =IFERROR(SUMIFS('Asset Value'!$F$4:$F$500,'Asset Value'!$C$4:$C$500,$A111,'Asset Value'!$B$4:$B$500,F$96)/SUMIFS('Asset Value'!$D$4:$D$500,'Asset Value'!$C$4:$C$500,$A111,'Asset Value'!$B$4:$B$500,F$96),0) -> 0 | G111: =IFERROR(SUMIFS('Asset Value'!$F$4:$F$500,'Asset Value'!$C$4:$C$500,$A111,'Asset Value'!$B$4:$B$500,G$96)/SUMIFS('Asset Value'!$D$4:$D$500,'Asset Value'!$C$4:$C$500,$A111,'Asset Value'!$B$4:$B$500,G$96),0) -> 0 | H111: =IFERROR(SUMIFS('Asset Value'!$F$4:$F$500,'Asset Value'!$C$4:$C$500,$A111,'Asset Value'!$B$4:$B$500,H$96)/SUMIFS('Asset Value'!$D$4:$D$500,'Asset Value'!$C$4:$C$500,$A111,'Asset Value'!$B$4:$B$500,H$96),0) -> 0 | I111: =IFERROR(SUMIFS('Asset Value'!$F$4:$F$500,'Asset Value'!$C$4:$C$500,$A111,'Asset Value'!$B$4:$B$500,I$96)/SUMIFS('Asset Value'!$D$4:$D$500,'Asset Value'!$C$4:$C$500,$A111,'Asset Value'!$B$4:$B$500,I$96),0) -> 0 | J111: =_xlfn.MINIFS($B$86:$I$86,$B111:$I111,">0") -> 2008 | K111: =_xlfn.MAXIFS($B$86:$I$86,$B111:$I111,">0") -> 2010 | L111: =INDEX($B111:$I111,MATCH(J111,$B$86:$I$86,0)) -> 1371.3827 | M111: =INDEX($B111:$I111,MATCH(K111,$B$86:$I$86,0)) -> 1699.1453 | N111: =M111/L111-1 -> 0.23900152 | O111: =IF(K111>J111,(M111/L111)^(1/(K111-J111))-1,"") -> 0.11310445
A112: Obs.: o preço médio do portfólio muda também com a composição (entrada/saída de fazendas); use o gráfico por fazenda para comparar like-for-like.
A113: Obs.: CAGR de fazendas com poucos anos (Pejuçara 2012-13, Palmeira 2008-10) é só indicativo.

Sheet Register
B3: FNP | C3: Farm Name | D3: State | E3: County | F3: (R$ 000) | G3: 2008 | H3: 2009 | I3: 2010 | J3: 2011 | K3: =J3+1 -> 2012 | L3: =K3+1 -> 2013 | M3: =L3+1 -> 2014 | N3: =M3+1 -> 2015
B4: 73 | C4: Fazenda Pamplona | D4: Goias | E4: Cristalina | F4: Asset Value | G4: =SUMIFS('Asset Value'!$F$4:$F$102,'Asset Value'!$B$4:$B$102,Register!G$3,'Asset Value'!$C$4:$C$102,Register!$C4)/1000 -> 143610 | H4: =SUMIFS('Asset Value'!$F$4:$F$102,'Asset Value'!$B$4:$B$102,Register!H$3,'Asset Value'!$C$4:$C$102,Register!$C4)/1000 -> 158220 | I4: =SUMIFS('Asset Value'!$F$4:$F$102,'Asset Value'!$B$4:$B$102,Register!I$3,'Asset Value'!$C$4:$C$102,Register!$C4)/1000 -> 164240 | J4: =SUMIFS('Asset Value'!$F$4:$F$102,'Asset Value'!$B$4:$B$102,Register!J$3,'Asset Value'!$C$4:$C$102,Register!$C4)/1000 -> 179570 | K4: =SUMIFS('Asset Value'!$F$4:$F$102,'Asset Value'!$B$4:$B$102,Register!K$3,'Asset Value'!$C$4:$C$102,Register!$C4)/1000 -> 215630 | L4: =SUMIFS('Asset Value'!$F$4:$F$102,'Asset Value'!$B$4:$B$102,Register!L$3,'Asset Value'!$C$4:$C$102,Register!$C4)/1000 -> 224342 | M4: =SUMIFS('Asset Value'!$F$4:$F$102,'Asset Value'!$B$4:$B$102,Register!M$3,'Asset Value'!$C$4:$C$102,Register!$C4)/1000 -> 269921 | N4: =SUMIFS('Asset Value'!$F$4:$F$102,'Asset Value'!$B$4:$B$102,Register!N$3,'Asset Value'!$C$4:$C$102,Register!$C4)/1000 -> 290900
F5: %YoY | H5: =H4/G4-1 -> 0.10173386 | I5: =I4/H4-1 -> 0.038048287 | J5: =J4/I4-1 -> 0.093339016 | K5: =K4/J4-1 -> 0.20081305 | L5: =L4/K4-1 -> 0.040402541 | M5: =M4/L4-1 -> 0.20316749 | N5: =N4/M4-1 -> 0.077722741
F6: Rent | G6: =SUMIFS(Rent!$E$3:$E$110,Rent!$C$3:$C$110,Register!G$3,Rent!$D$3:$D$110,Register!$C4)/1000 -> 5764.1165 | H6: =SUMIFS(Rent!$E$3:$E$110,Rent!$C$3:$C$110,Register!H$3,Rent!$D$3:$D$110,Register!$C4)/1000 -> 5432.8454 | I6: =SUMIFS(Rent!$E$3:$E$110,Rent!$C$3:$C$110,Register!I$3,Rent!$D$3:$D$110,Register!$C4)/1000 -> 5962.8791 | J6: =SUMIFS(Rent!$E$3:$E$110,Rent!$C$3:$C$110,Register!J$3,Rent!$D$3:$D$110,Register!$C4)/1000 -> 4000.309 | K6: =SUMIFS(Rent!$E$3:$E$110,Rent!$C$3:$C$110,Register!K$3,Rent!$D$3:$D$110,Register!$C4)/1000 -> 6522 | L6: =SUMIFS(Rent!$E$3:$E$110,Rent!$C$3:$C$110,Register!L$3,Rent!$D$3:$D$110,Register!$C4)/1000 -> 5902 | M6: =SUMIFS(Rent!$E$3:$E$110,Rent!$C$3:$C$110,Register!M$3,Rent!$D$3:$D$110,Register!$C4)/1000 -> 6567 | N6: =SUMIFS(Rent!$E$3:$E$110,Rent!$C$3:$C$110,Register!N$3,Rent!$D$3:$D$110,Register!$C4)/1000 -> 8312
F7: %YoY | H7: =H6/G6-1 -> -0.057471264 | I7: =I6/H6-1 -> 0.097560976 | J7: =J6/I6-1 -> -0.32913129 | K7: =K6/J6-1 -> 0.63037404 | L7: =L6/K6-1 -> -0.095062864 | M7: =M6/L6-1 -> 0.11267367 | N7: =N6/M6-1 -> 0.26572255
F8: %Yield | G8: =G6/G4 -> 0.040137292 | H8: =H6/H4 -> 0.034337286 | I8: =I6/I4 -> 0.036305888 | J8: =J6/J4 -> 0.022277157 | K8: =K6/K4 -> 0.030246255 | L8: =L6/L4 -> 0.026308048 | M8: =M6/M4 -> 0.024329341 | N8: =N6/N4 -> 0.028573393
B9: 41 | C9: Fazenda Planalto | D9: Mato Grosso Sul | E9: Costa Rica | F9: Asset Value | G9: =SUMIFS('Asset Value'!$F$4:$F$102,'Asset Value'!$B$4:$B$102,Register!G$3,'Asset Value'!$C$4:$C$102,Register!$C9)/1000 -> 207710 | H9: =SUMIFS('Asset Value'!$F$4:$F$102,'Asset Value'!$B$4:$B$102,Register!H$3,'Asset Value'!$C$4:$C$102,Register!$C9)/1000 -> 234810 | I9: =SUMIFS('Asset Value'!$F$4:$F$102,'Asset Value'!$B$4:$B$102,Register!I$3,'Asset Value'!$C$4:$C$102,Register!$C9)/1000 -> 241810 | J9: =SUMIFS('Asset Value'!$F$4:$F$102,'Asset Value'!$B$4:$B$102,Register!J$3,'Asset Value'!$C$4:$C$102,Register!$C9)/1000 -> 273920 | K9: =SUMIFS('Asset Value'!$F$4:$F$102,'Asset Value'!$B$4:$B$102,Register!K$3,'Asset Value'!$C$4:$C$102,Register!$C9)/1000 -> 322340 | L9: =SUMIFS('Asset Value'!$F$4:$F$102,'Asset Value'!$B$4:$B$102,Register!L$3,'Asset Value'!$C$4:$C$102,Register!$C9)/1000 -> 331712 | M9: =SUMIFS('Asset Value'!$F$4:$F$102,'Asset Value'!$B$4:$B$102,Register!M$3,'Asset Value'!$C$4:$C$102,Register!$C9)/1000 -> 453258 | N9: =SUMIFS('Asset Value'!$F$4:$F$102,'Asset Value'!$B$4:$B$102,Register!N$3,'Asset Value'!$C$4:$C$102,Register!$C9)/1000 -> 473550
F10: %YoY | H10: =H9/G9-1 -> 0.13047037 | I10: =I9/H9-1 -> 0.029811337 | J10: =J9/I9-1 -> 0.13279021 | K10: =K9/J9-1 -> 0.17676694 | L10: =L9/K9-1 -> 0.02907489 | M10: =M9/L9-1 -> 0.36642027 | N10: =N9/M9-1 -> 0.044769204
F11: Rent | G11: =SUMIFS(Rent!$E$3:$E$110,Rent!$C$3:$C$110,Register!G$3,Rent!$D$3:$D$110,Register!$C9)/1000 -> 6078.8944 | H11: =SUMIFS(Rent!$E$3:$E$110,Rent!$C$3:$C$110,Register!H$3,Rent!$D$3:$D$110,Register!$C9)/1000 -> 5934.1588 | I11: =SUMIFS(Rent!$E$3:$E$110,Rent!$C$3:$C$110,Register!I$3,Rent!$D$3:$D$110,Register!$C9)/1000 -> 6802.5723 | J11: =SUMIFS(Rent!$E$3:$E$110,Rent!$C$3:$C$110,Register!J$3,Rent!$D$3:$D$110,Register!$C9)/1000 -> 4563.6752 | K11: =SUMIFS(Rent!$E$3:$E$110,Rent!$C$3:$C$110,Register!K$3,Rent!$D$3:$D$110,Register!$C9)/1000 -> 7795 | L11: =SUMIFS(Rent!$E$3:$E$110,Rent!$C$3:$C$110,Register!L$3,Rent!$D$3:$D$110,Register!$C9)/1000 -> 7483 | M11: =SUMIFS(Rent!$E$3:$E$110,Rent!$C$3:$C$110,Register!M$3,Rent!$D$3:$D$110,Register!$C9)/1000 -> 10660 | N11: =SUMIFS(Rent!$E$3:$E$110,Rent!$C$3:$C$110,Register!N$3,Rent!$D$3:$D$110,Register!$C9)/1000 -> 13057
F12: %YoY | H12: =H11/G11-1 -> -0.023809524 | I12: =I11/H11-1 -> 0.14634146 | J12: =J11/I11-1 -> -0.32912507 | K12: =K11/J11-1 -> 0.70805319 | L12: =L11/K11-1 -> -0.040025657 | M12: =M11/L11-1 -> 0.42456234 | N12: =N11/M11-1 -> 0.22485929
F13: %Yield | G13: =G11/G9 -> 0.029266258 | H13: =H11/H9 -> 0.025272172 | I13: =I11/I9 -> 0.02813189 | J13: =J11/J9 -> 0.016660613 | K13: =K11/K9 -> 0.02418254 | L13: =L11/L9 -> 0.022558726 | M13: =M11/M9 -> 0.023518614 | N13: =N11/N9 -> 0.02757259
B14: 114 | C14: Fazenda Planeste | D14: Maranhao | E14: Balsas | F14: Asset Value | G14: =SUMIFS('Asset Value'!$F$4:$F$102,'Asset Value'!$B$4:$B$102,Register!G$3,'Asset Value'!$C$4:$C$102,Register!$C14)/1000 -> 106940 | H14: =SUMIFS('Asset Value'!$F$4:$F$102,'Asset Value'!$B$4:$B$102,Register!H$3,'Asset Value'!$C$4:$C$102,Register!$C14)/1000 -> 118040 | I14: =SUMIFS('Asset Value'!$F$4:$F$102,'Asset Value'!$B$4:$B$102,Register!I$3,'Asset Value'!$C$4:$C$102,Register!$C14)/1000 -> 142170 | J14: =SUMIFS('Asset Value'!$F$4:$F$102,'Asset Value'!$B$4:$B$102,Register!J$3,'Asset Value'!$C$4:$C$102,Register!$C14)/1000 -> 172970 | K14: =SUMIFS('Asset Value'!$F$4:$F$102,'Asset Value'!$B$4:$B$102,Register!K$3,'Asset Value'!$C$4:$C$102,Register!$C14)/1000 -> 197471 | L14: =SUMIFS('Asset Value'!$F$4:$F$102,'Asset Value'!$B$4:$B$102,Register!L$3,'Asset Value'!$C$4:$C$102,Register!$C14)/1000 -> 220203 | M14: =SUMIFS('Asset Value'!$F$4:$F$102,'Asset Value'!$B$4:$B$102,Register!M$3,'Asset Value'!$C$4:$C$102,Register!$C14)/1000 -> 229674 | N14: =SUMIFS('Asset Value'!$F$4:$F$102,'Asset Value'!$B$4:$B$102,Register!N$3,'Asset Value'!$C$4:$C$102,Register!$C14)/1000 -> 234550
F15: %YoY | H15: =H14/G14-1 -> 0.10379652 | I15: =I14/H14-1 -> 0.20442223 | J15: =J14/I14-1 -> 0.21664205 | K15: =K14/J14-1 -> 0.14164884 | L15: =L14/K14-1 -> 0.11511564 | M15: =M14/L14-1 -> 0.043010313 | N15: =N14/M14-1 -> 0.021230091
F16: Rent | G16: =SUMIFS(Rent!$E$3:$E$110,Rent!$C$3:$C$110,Register!G$3,Rent!$D$3:$D$110,Register!$C14)/1000 -> 3727.4927 | H16: =SUMIFS(Rent!$E$3:$E$110,Rent!$C$3:$C$110,Register!H$3,Rent!$D$3:$D$110,Register!$C14)/1000 -> 3502.9449 | I16: =SUMIFS(Rent!$E$3:$E$110,Rent!$C$3:$C$110,Register!I$3,Rent!$D$3:$D$110,Register!$C14)/1000 -> 3907.1309 | J16: =SUMIFS(Rent!$E$3:$E$110,Rent!$C$3:$C$110,Register!J$3,Rent!$D$3:$D$110,Register!$C14)/1000 -> 4417.4492 | K16: =SUMIFS(Rent!$E$3:$E$110,Rent!$C$3:$C$110,Register!K$3,Rent!$D$3:$D$110,Register!$C14)/1000 -> 9821 | L16: =SUMIFS(Rent!$E$3:$E$110,Rent!$C$3:$C$110,Register!L$3,Rent!$D$3:$D$110,Register!$C14)/1000 -> 7371 | M16: =SUMIFS(Rent!$E$3:$E$110,Rent!$C$3:$C$110,Register!M$3,Rent!$D$3:$D$110,Register!$C14)/1000 -> 8241 | N16: =SUMIFS(Rent!$E$3:$E$110,Rent!$C$3:$C$110,Register!N$3,Rent!$D$3:$D$110,Register!$C14)/1000 -> 8398
F17: %YoY | H17: =H16/G16-1 -> -0.060240964 | I17: =I16/H16-1 -> 0.11538462 | J17: =J16/I16-1 -> 0.13061206 | K17: =K16/J16-1 -> 1.2232287 | L17: =L16/K16-1 -> -0.24946543 | M17: =M16/L16-1 -> 0.11803012 | N17: =N16/M16-1 -> 0.019051086
F18: %Yield | G18: =G16/G14 -> 0.034855925 | H18: =H16/H14 -> 0.029675914 | I18: =I16/I14 -> 0.027482105 | J18: =J16/J14 -> 0.025538817 | K18: =K16/K14 -> 0.049733885 | L18: =L16/L14 -> 0.033473658 | M18: =M16/M14 -> 0.035881293 | N18: =N16/N14 -> 0.035804732
B19: 82 | C19: Fazenda Panorama | D19: Bahia | E19: Correntina | F19: Asset Value | G19: =SUMIFS('Asset Value'!$F$4:$F$102,'Asset Value'!$B$4:$B$102,Register!G$3,'Asset Value'!$C$4:$C$102,Register!$C19)/1000 -> 75090 | H19: =SUMIFS('Asset Value'!$F$4:$F$102,'Asset Value'!$B$4:$B$102,Register!H$3,'Asset Value'!$C$4:$C$102,Register!$C19)/1000 -> 86360 | I19: =SUMIFS('Asset Value'!$F$4:$F$102,'Asset Value'!$B$4:$B$102,Register!I$3,'Asset Value'!$C$4:$C$102,Register!$C19)/1000 -> 102810 | J19: =SUMIFS('Asset Value'!$F$4:$F$102,'Asset Value'!$B$4:$B$102,Register!J$3,'Asset Value'!$C$4:$C$102,Register!$C19)/1000 -> 146710 | K19: =SUMIFS('Asset Value'!$F$4:$F$102,'Asset Value'!$B$4:$B$102,Register!K$3,'Asset Value'!$C$4:$C$102,Register!$C19)/1000 -> 167470 | L19: =SUMIFS('Asset Value'!$F$4:$F$102,'Asset Value'!$B$4:$B$102,Register!L$3,'Asset Value'!$C$4:$C$102,Register!$C19)/1000 -> 145456 | M19: =SUMIFS('Asset Value'!$F$4:$F$102,'Asset Value'!$B$4:$B$102,Register!M$3,'Asset Value'!$C$4:$C$102,Register!$C19)/1000 -> 156350 | N19: =SUMIFS('Asset Value'!$F$4:$F$102,'Asset Value'!$B$4:$B$102,Register!N$3,'Asset Value'!$C$4:$C$102,Register!$C19)/1000 -> 166430
F20: %YoY | H20: =H19/G19-1 -> 0.15008656 | I20: =I19/H19-1 -> 0.1904817 | J20: =J19/I19-1 -> 0.42700126 | K20: =K19/J19-1 -> 0.14150365 | L20: =L19/K19-1 -> -0.13145041 | M20: =M19/L19-1 -> 0.074895501 | N20: =N19/M19-1 -> 0.064470739
F21: Rent | G21: =SUMIFS(Rent!$E$3:$E$110,Rent!$C$3:$C$110,Register!G$3,Rent!$D$3:$D$110,Register!$C19)/1000 -> 2181.24 | H21: =SUMIFS(Rent!$E$3:$E$110,Rent!$C$3:$C$110,Register!H$3,Rent!$D$3:$D$110,Register!$C19)/1000 -> 2049.84 | I21: =SUMIFS(Rent!$E$3:$E$110,Rent!$C$3:$C$110,Register!I$3,Rent!$D$3:$D$110,Register!$C19)/1000 -> 2897.28 | J21: =SUMIFS(Rent!$E$3:$E$110,Rent!$C$3:$C$110,Register!J$3,Rent!$D$3:$D$110,Register!$C19)/1000 -> 3924.8869 | K21: =SUMIFS(Rent!$E$3:$E$110,Rent!$C$3:$C$110,Register!K$3,Rent!$D$3:$D$110,Register!$C19)/1000 -> 7989 | L21: =SUMIFS(Rent!$E$3:$E$110,Rent!$C$3:$C$110,Register!L$3,Rent!$D$3:$D$110,Register!$C19)/1000 -> 5372 | M21: =SUMIFS(Rent!$E$3:$E$110,Rent!$C$3:$C$110,Register!M$3,Rent!$D$3:$D$110,Register!$C19)/1000 -> 5792 | N21: =SUMIFS(Rent!$E$3:$E$110,Rent!$C$3:$C$110,Register!N$3,Rent!$D$3:$D$110,Register!$C19)/1000 -> 6119
F22: %YoY | H22: =H21/G21-1 -> -0.060240964 | I22: =I21/H21-1 -> 0.41341763 | J22: =J21/I21-1 -> 0.35467986 | K22: =K21/J21-1 -> 1.0354727 | L22: =L21/K21-1 -> -0.32757542 | M22: =M21/L21-1 -> 0.078183172 | N22: =N21/M21-1 -> 0.056457182
F23: %Yield | G23: =G21/G19 -> 0.029048342 | H23: =H21/H19 -> 0.023735989 | I23: =I21/I19 -> 0.028180916 | J23: =J21/J19 -> 0.026752688 | K23: =K21/K19 -> 0.047704066 | L23: =L21/L19 -> 0.036932131 | M23: =M21/M19 -> 0.037045091 | N23: =N21/N19 -> 0.036766208
B24: 82 | C24: Fazenda Piratini | D24: Bahia | E24: Jaborandi | F24: Asset Value | G24: =SUMIFS('Asset Value'!$F$4:$F$102,'Asset Value'!$B$4:$B$102,Register!G$3,'Asset Value'!$C$4:$C$102,Register!$C24)/1000 -> 58920 | H24: =SUMIFS('Asset Value'!$F$4:$F$102,'Asset Value'!$B$4:$B$102,Register!H$3,'Asset Value'!$C$4:$C$102,Register!$C24)/1000 -> 94840 | I24: =SUMIFS('Asset Value'!$F$4:$F$102,'Asset Value'!$B$4:$B$102,Register!I$3,'Asset Value'!$C$4:$C$102,Register!$C24)/1000 -> 81810 | J24: =SUMIFS('Asset Value'!$F$4:$F$102,'Asset Value'!$B$4:$B$102,Register!J$3,'Asset Value'!$C$4:$C$102,Register!$C24)/1000 -> 117020 | K24: =SUMIFS('Asset Value'!$F$4:$F$102,'Asset Value'!$B$4:$B$102,Register!K$3,'Asset Value'!$C$4:$C$102,Register!$C24)/1000 -> 133583 | L24: =SUMIFS('Asset Value'!$F$4:$F$102,'Asset Value'!$B$4:$B$102,Register!L$3,'Asset Value'!$C$4:$C$102,Register!$C24)/1000 -> 176404 | M24: =SUMIFS('Asset Value'!$F$4:$F$102,'Asset Value'!$B$4:$B$102,Register!M$3,'Asset Value'!$C$4:$C$102,Register!$C24)/1000 -> 198210 | N24: =SUMIFS('Asset Value'!$F$4:$F$102,'Asset Value'!$B$4:$B$102,Register!N$3,'Asset Value'!$C$4:$C$102,Register!$C24)/1000 -> 222860
F25: %YoY | H25: =H24/G24-1 -> 0.60964019 | I25: =I24/H24-1 -> -0.13738929 | J25: =J24/I24-1 -> 0.43038748 | K25: =K24/J24-1 -> 0.14153991 | L25: =L24/K24-1 -> 0.32055726 | M25: =M24/L24-1 -> 0.12361398 | N25: =N24/M24-1 -> 0.12436305
F26: Rent | G26: =SUMIFS(Rent!$E$3:$E$110,Rent!$C$3:$C$110,Register!G$3,Rent!$D$3:$D$110,Register!$C24)/1000 -> 0 | H26: =SUMIFS(Rent!$E$3:$E$110,Rent!$C$3:$C$110,Register!H$3,Rent!$D$3:$D$110,Register!$C24)/1000 -> 0 | I26: =SUMIFS(Rent!$E$3:$E$110,Rent!$C$3:$C$110,Register!I$3,Rent!$D$3:$D$110,Register!$C24)/1000 -> 455 | J26: =SUMIFS(Rent!$E$3:$E$110,Rent!$C$3:$C$110,Register!J$3,Rent!$D$3:$D$110,Register!$C24)/1000 -> 2193.4205 | K26: =SUMIFS(Rent!$E$3:$E$110,Rent!$C$3:$C$110,Register!K$3,Rent!$D$3:$D$110,Register!$C24)/1000 -> 3466 | L26: =SUMIFS(Rent!$E$3:$E$110,Rent!$C$3:$C$110,Register!L$3,Rent!$D$3:$D$110,Register!$C24)/1000 -> 2818 | M26: =SUMIFS(Rent!$E$3:$E$110,Rent!$C$3:$C$110,Register!M$3,Rent!$D$3:$D$110,Register!$C24)/1000 -> 3235 | N26: =SUMIFS(Rent!$E$3:$E$110,Rent!$C$3:$C$110,Register!N$3,Rent!$D$3:$D$110,Register!$C24)/1000 -> 3602
F27: %YoY | H27: =H26/G26-1 -> #DIV/0! | I27: =I26/H26-1 -> #DIV/0! | J27: =J26/I26-1 -> 3.8207044 | K27: =K26/J26-1 -> 0.58018038 | L27: =L26/K26-1 -> -0.18695903 | M27: =M26/L26-1 -> 0.14797729 | N27: =N26/M26-1 -> 0.11344668
F28: %Yield | G28: =G26/G24 -> 0 | H28: =H26/H24 -> 0 | I28: =I26/I24 -> 0.0055616673 | J28: =J26/J24 -> 0.018743979 | K28: =K26/K24 -> 0.025946415 | L28: =L26/L24 -> 0.015974694 | M28: =M26/M24 -> 0.016321074 | N28: =N26/N24 -> 0.016162613
B29: 82 | C29: Fazenda Palmares | D29: Bahia | E29: Barreiras | F29: Asset Value | G29: =SUMIFS('Asset Value'!$F$4:$F$102,'Asset Value'!$B$4:$B$102,Register!G$3,'Asset Value'!$C$4:$C$102,Register!$C29)/1000 -> 0 | H29: =SUMIFS('Asset Value'!$F$4:$F$102,'Asset Value'!$B$4:$B$102,Register!H$3,'Asset Value'!$C$4:$C$102,Register!$C29)/1000 -> 22780 | I29: =SUMIFS('Asset Value'!$F$4:$F$102,'Asset Value'!$B$4:$B$102,Register!I$3,'Asset Value'!$C$4:$C$102,Register!$C29)/1000 -> 46320 | J29: =SUMIFS('Asset Value'!$F$4:$F$102,'Asset Value'!$B$4:$B$102,Register!J$3,'Asset Value'!$C$4:$C$102,Register!$C29)/1000 -> 83990 | K29: =SUMIFS('Asset Value'!$F$4:$F$102,'Asset Value'!$B$4:$B$102,Register!K$3,'Asset Value'!$C$4:$C$102,Register!$C29)/1000 -> 102260 | L29: =SUMIFS('Asset Value'!$F$4:$F$102,'Asset Value'!$B$4:$B$102,Register!L$3,'Asset Value'!$C$4:$C$102,Register!$C29)/1000 -> 173185 | M29: =SUMIFS('Asset Value'!$F$4:$F$102,'Asset Value'!$B$4:$B$102,Register!M$3,'Asset Value'!$C$4:$C$102,Register!$C29)/1000 -> 183096 | N29: =SUMIFS('Asset Value'!$F$4:$F$102,'Asset Value'!$B$4:$B$102,Register!N$3,'Asset Value'!$C$4:$C$102,Register!$C29)/1000 -> 187600
F30: %YoY | H30: =H29/G29-1 -> #DIV/0! | I30: =I29/H29-1 -> 1.0333626 | J30: =J29/I29-1 -> 0.81325561 | K30: =K29/J29-1 -> 0.2175259 | L30: =L29/K29-1 -> 0.6935752 | M30: =M29/L29-1 -> 0.05722782 | N30: =N29/M29-1 -> 0.024599117
F31: Rent | G31: =SUMIFS(Rent!$E$3:$E$110,Rent!$C$3:$C$110,Register!G$3,Rent!$D$3:$D$110,Register!$C29)/1000 -> 565.677 | H31: =SUMIFS(Rent!$E$3:$E$110,Rent!$C$3:$C$110,Register!H$3,Rent!$D$3:$D$110,Register!$C29)/1000 -> 1155.0427 | I31: =SUMIFS(Rent!$E$3:$E$110,Rent!$C$3:$C$110,Register!I$3,Rent!$D$3:$D$110,Register!$C29)/1000 -> 2568.87 | J31: =SUMIFS(Rent!$E$3:$E$110,Rent!$C$3:$C$110,Register!J$3,Rent!$D$3:$D$110,Register!$C29)/1000 -> 4695.2925 | K31: =SUMIFS(Rent!$E$3:$E$110,Rent!$C$3:$C$110,Register!K$3,Rent!$D$3:$D$110,Register!$C29)/1000 -> 7902 | L31: =SUMIFS(Rent!$E$3:$E$110,Rent!$C$3:$C$110,Register!L$3,Rent!$D$3:$D$110,Register!$C29)/1000 -> 7315 | M31: =SUMIFS(Rent!$E$3:$E$110,Rent!$C$3:$C$110,Register!M$3,Rent!$D$3:$D$110,Register!$C29)/1000 -> 7608 | N31: =SUMIFS(Rent!$E$3:$E$110,Rent!$C$3:$C$110,Register!N$3,Rent!$D$3:$D$110,Register!$C29)/1000 -> 10130
F32: %YoY | H32: =H31/G31-1 -> 1.0418768 | I32: =I31/H31-1 -> 1.2240476 | J32: =J31/I31-1 -> 0.8277657 | K32: =K31/J31-1 -> 0.68296225 | L32: =L31/K31-1 -> -0.074284991 | M32: =M31/L31-1 -> 0.040054682 | N32: =N31/M31-1 -> 0.33149317
F33: %Yield | G33: =G31/G29 -> #DIV/0! | H33: =H31/H29 -> 0.050704246 | I33: =I31/I29 -> 0.055459197 | J33: =J31/J29 -> 0.055902994 | K33: =K31/K29 -> 0.077273616 | L33: =L31/L29 -> 0.042238069 | M33: =M31/M29 -> 0.041551973 | N33: =N31/N29 -> 0.053997868
B34: 114 | C34: Fazenda Parnaíba | D34: Maranhao | E34: Tasso Fragoso | F34: Asset Value | G34: =SUMIFS('Asset Value'!$F$4:$F$102,'Asset Value'!$B$4:$B$102,Register!G$3,'Asset Value'!$C$4:$C$102,Register!$C34)/1000 -> 156660 | H34: =SUMIFS('Asset Value'!$F$4:$F$102,'Asset Value'!$B$4:$B$102,Register!H$3,'Asset Value'!$C$4:$C$102,Register!$C34)/1000 -> 207350 | I34: =SUMIFS('Asset Value'!$F$4:$F$102,'Asset Value'!$B$4:$B$102,Register!I$3,'Asset Value'!$C$4:$C$102,Register!$C34)/1000 -> 199850 | J34: =SUMIFS('Asset Value'!$F$4:$F$102,'Asset Value'!$B$4:$B$102,Register!J$3,'Asset Value'!$C$4:$C$102,Register!$C34)/1000 -> 222570 | K34: =SUMIFS('Asset Value'!$F$4:$F$102,'Asset Value'!$B$4:$B$102,Register!K$3,'Asset Value'!$C$4:$C$102,Register!$C34)/1000 -> 262140 | L34: =SUMIFS('Asset Value'!$F$4:$F$102,'Asset Value'!$B$4:$B$102,Register!L$3,'Asset Value'!$C$4:$C$102,Register!$C34)/1000 -> 305364 | M34: =SUMIFS('Asset Value'!$F$4:$F$102,'Asset Value'!$B$4:$B$102,Register!M$3,'Asset Value'!$C$4:$C$102,Register!$C34)/1000 -> 346990 | N34: =SUMIFS('Asset Value'!$F$4:$F$102,'Asset Value'!$B$4:$B$102,Register!N$3,'Asset Value'!$C$4:$C$102,Register!$C34)/1000 -> 412090
F35: %YoY | H35: =H34/G34-1 -> 0.32356696 | I35: =I34/H34-1 -> -0.036170726 | J35: =J34/I34-1 -> 0.11368526 | K35: =K34/J34-1 -> 0.17778676 | L35: =L34/K34-1 -> 0.16488899 | M35: =M34/L34-1 -> 0.136316 | N35: =N34/M34-1 -> 0.18761348
F36: Rent | G36: =SUMIFS(Rent!$E$3:$E$110,Rent!$C$3:$C$110,Register!G$3,Rent!$D$3:$D$110,Register!$C34)/1000 -> 0 | H36: =SUMIFS(Rent!$E$3:$E$110,Rent!$C$3:$C$110,Register!H$3,Rent!$D$3:$D$110,Register!$C34)/1000 -> 0 | I36: =SUMIFS(Rent!$E$3:$E$110,Rent!$C$3:$C$110,Register!I$3,Rent!$D$3:$D$110,Register!$C34)/1000 -> 0 | J36: =SUMIFS(Rent!$E$3:$E$110,Rent!$C$3:$C$110,Register!J$3,Rent!$D$3:$D$110,Register!$C34)/1000 -> 0 | K36: =SUMIFS(Rent!$E$3:$E$110,Rent!$C$3:$C$110,Register!K$3,Rent!$D$3:$D$110,Register!$C34)/1000 -> 0 | L36: =SUMIFS(Rent!$E$3:$E$110,Rent!$C$3:$C$110,Register!L$3,Rent!$D$3:$D$110,Register!$C34)/1000 -> 0 | M36: =SUMIFS(Rent!$E$3:$E$110,Rent!$C$3:$C$110,Register!M$3,Rent!$D$3:$D$110,Register!$C34)/1000 -> 151 | N36: =SUMIFS(Rent!$E$3:$E$110,Rent!$C$3:$C$110,Register!N$3,Rent!$D$3:$D$110,Register!$C34)/1000 -> 159
F37: %YoY | H37: =H36/G36-1 -> #DIV/0! | I37: =I36/H36-1 -> #DIV/0! | J37: =J36/I36-1 -> #DIV/0! | K37: =K36/J36-1 -> #DIV/0! | L37: =L36/K36-1 -> #DIV/0! | M37: =M36/L36-1 -> #DIV/0! | N37: =N36/M36-1 -> 0.052980132
F38: %Yield | G38: =G36/G34 -> 0 | H38: =H36/H34 -> 0 | I38: =I36/I34 -> 0 | J38: =J36/J34 -> 0 | K38: =K36/K34 -> 0 | L38: =L36/L34 -> 0 | M38: =M36/M34 -> 0.00043517104 | N38: =N36/N34 -> 0.00038583805
B39: 64 | C39: Fazenda Paiaguás | D39: Mato Grosso | E39: Diamantino | F39: Asset Value | G39: =(SUMIFS('Asset Value'!$F$4:$F$102,'Asset Value'!$B$4:$B$102,Register!G$3,'Asset Value'!$C$4:$C$102,Register!$C39)/1000)+(G44) -> 218840 | H39: =(SUMIFS('Asset Value'!$F$4:$F$102,'Asset Value'!$B$4:$B$102,Register!H$3,'Asset Value'!$C$4:$C$102,Register!$C39)/1000)+(H44) -> 265050 | I39: =(SUMIFS('Asset Value'!$F$4:$F$102,'Asset Value'!$B$4:$B$102,Register!I$3,'Asset Value'!$C$4:$C$102,Register!$C39)/1000)+(I44) -> 243950 | J39: =(SUMIFS('Asset Value'!$F$4:$F$102,'Asset Value'!$B$4:$B$102,Register!J$3,'Asset Value'!$C$4:$C$102,Register!$C39)/1000)+(J44) -> 279570 | K39: =(SUMIFS('Asset Value'!$F$4:$F$102,'Asset Value'!$B$4:$B$102,Register!K$3,'Asset Value'!$C$4:$C$102,Register!$C39)/1000)+(K44) -> 332180 | L39: =(SUMIFS('Asset Value'!$F$4:$F$102,'Asset Value'!$B$4:$B$102,Register!L$3,'Asset Value'!$C$4:$C$102,Register!$C39)/1000)+(L44) -> 341232 | M39: =(SUMIFS('Asset Value'!$F$4:$F$102,'Asset Value'!$B$4:$B$102,Register!M$3,'Asset Value'!$C$4:$C$102,Register!$C39)/1000)+(M44) -> 420555 | N39: =(SUMIFS('Asset Value'!$F$4:$F$102,'Asset Value'!$B$4:$B$102,Register!N$3,'Asset Value'!$C$4:$C$102,Register!$C39)/1000)+(N44) -> 450910
F40: %YoY | H40: =H39/G39-1 -> 0.21115884 | I40: =I39/H39-1 -> -0.079607621 | J40: =J39/I39-1 -> 0.14601353 | K40: =K39/J39-1 -> 0.18818185 | L40: =L39/K39-1 -> 0.027250286 | M40: =M39/L39-1 -> 0.23246061 | N40: =N39/M39-1 -> 0.072178431
F41: Rent | G41: =(SUMIFS(Rent!$E$3:$E$110,Rent!$C$3:$C$110,Register!G$3,Rent!$D$3:$D$110,Register!$C39)/1000)+(G46) -> 7507.2496 | H41: =(SUMIFS(Rent!$E$3:$E$110,Rent!$C$3:$C$110,Register!H$3,Rent!$D$3:$D$110,Register!$C39)/1000)+(H46) -> 7007.6113 | I41: =(SUMIFS(Rent!$E$3:$E$110,Rent!$C$3:$C$110,Register!I$3,Rent!$D$3:$D$110,Register!$C39)/1000)+(I46) -> 8841.9566 | J41: =(SUMIFS(Rent!$E$3:$E$110,Rent!$C$3:$C$110,Register!J$3,Rent!$D$3:$D$110,Register!$C39)/1000)+(J46) -> 4976.6418 | K41: =(SUMIFS(Rent!$E$3:$E$110,Rent!$C$3:$C$110,Register!K$3,Rent!$D$3:$D$110,Register!$C39)/1000)+(K46) -> 10538 | L41: =(SUMIFS(Rent!$E$3:$E$110,Rent!$C$3:$C$110,Register!L$3,Rent!$D$3:$D$110,Register!$C39)/1000)+(L46) -> 9884 | M41: =(SUMIFS(Rent!$E$3:$E$110,Rent!$C$3:$C$110,Register!M$3,Rent!$D$3:$D$110,Register!$C39)/1000)+(M46) -> 15146 | N41: =(SUMIFS(Rent!$E$3:$E$110,Rent!$C$3:$C$110,Register!N$3,Rent!$D$3:$D$110,Register!$C39)/1000)+(N46) -> 17733
F42: %YoY | H42: =H41/G41-1 -> -0.066554101 | I42: =I41/H41-1 -> 0.26176471 | J42: =J41/I41-1 -> -0.43715605 | K42: =K41/J41-1 -> 1.1174922 | L42: =L41/K41-1 -> -0.062061112 | M42: =M41/L41-1 -> 0.53237556 | N42: =N41/M41-1 -> 0.17080417
...

Sheet Asset Value
A3: Date | B3: Ano | C3: Fazenda | D3: Area Agricultavel | E3: Valor (R$ 000) | F3: Valor (R$) | G3: (R$/ha) | H3: PTAX (R$/US$) | I3: Valor (US$) | J3: (US$/ha) | L3: PTAX = cotação de compra do Banco Central na data do Date (ou último dia útil anterior). Ver aba PTAX.
A4: 39568 | B4: 2008 | C4: Fazenda Pamplona | D4: 17094 | E4: 143610 | F4: =E4*1000 -> 143610000 | G4: =F4/D4 -> 8401.1934 | H4: =IFERROR(INDEX(PTAX!$C$5:$C$5000,MATCH($A4,PTAX!$B$5:$B$5000,1)),"") -> 1.6864 | I4: =IF(H4="","",F4/H4) -> 85157732 | J4: =IF(H4="","",I4/D4) -> 4981.7323
A5: 39568 | B5: 2008 | C5: Fazenda Planalto | D5: 17489 | E5: 207710 | F5: =E5*1000 -> 207710000 | G5: =F5/D5 -> 11876.608 | H5: =IFERROR(INDEX(PTAX!$C$5:$C$5000,MATCH($A5,PTAX!$B$5:$B$5000,1)),"") -> 1.6864 | I5: =IF(H5="","",F5/H5) -> 1.2316769e+08 | J5: =IF(H5="","",I5/D5) -> 7042.5807
A6: 39568 | B6: 2008 | C6: Fazenda Planeste | D6: 18256 | E6: 106940 | F6: =E6*1000 -> 106940000 | G6: =F6/D6 -> 5857.8002 | H6: =IFERROR(INDEX(PTAX!$C$5:$C$5000,MATCH($A6,PTAX!$B$5:$B$5000,1)),"") -> 1.6864 | I6: =IF(H6="","",F6/H6) -> 63413188 | J6: =IF(H6="","",I6/D6) -> 3473.5532
A7: 39568 | B7: 2008 | C7: Fazenda Parnaíba | D7: 26084 | E7: 156660 | F7: =E7*1000 -> 156660000 | G7: =F7/D7 -> 6005.9807 | H7: =IFERROR(INDEX(PTAX!$C$5:$C$5000,MATCH($A7,PTAX!$B$5:$B$5000,1)),"") -> 1.6864 | I7: =IF(H7="","",F7/H7) -> 92896110 | J7: =IF(H7="","",I7/D7) -> 3561.4212
A8: 39568 | B8: 2008 | C8: Fazenda Palmeira | D8: 14963 | E8: 20520 | F8: =E8*1000 -> 20520000 | G8: =F8/D8 -> 1371.3827 | H8: =IFERROR(INDEX(PTAX!$C$5:$C$5000,MATCH($A8,PTAX!$B$5:$B$5000,1)),"") -> 1.6864 | I8: =IF(H8="","",F8/H8) -> 12167932 | J8: =IF(H8="","",I8/D8) -> 813.20134
A9: 39568 | B9: 2008 | C9: Fazenda Planorte | D9: 13159 | E9: 108480 | F9: =E9*1000 -> 108480000 | G9: =F9/D9 -> 8243.7875 | H9: =IFERROR(INDEX(PTAX!$C$5:$C$5000,MATCH($A9,PTAX!$B$5:$B$5000,1)),"") -> 1.6864 | I9: =IF(H9="","",F9/H9) -> 64326376 | J9: =IF(H9="","",I9/D9) -> 4888.3939
A10: 39568 | B10: 2008 | C10: Fazenda Paiaguás | D10: 26257 | E10: 218840 | F10: =E10*1000 -> 218840000 | G10: =F10/D10 -> 8334.5394 | H10: =IFERROR(INDEX(PTAX!$C$5:$C$5000,MATCH($A10,PTAX!$B$5:$B$5000,1)),"") -> 1.6864 | I10: =IF(H10="","",F10/H10) -> 1.2976755e+08 | J10: =IF(H10="","",I10/D10) -> 4942.2079
