Workbook

Sheet Série Temporal
A1: Arrendamento anual a pagar por fazenda (R$ mil) – preço anual em 31/dez de cada ano
A2: Fonte: Notas Explicativas às Demonstrações Financeiras SLC Agrícola – nota 14 (Saldos e transações com partes relacionadas), contratos de arrendamento a pagar. Valores digitados a partir da imagem (azul = entrada).
A4: Fazenda | B4: 2012 | C4: 2013 | D4: 2014 | E4: 2015 | F4: 2016 | G4: 2017
A5: Safra | B5: 2012/13 | C5: 2013/14 | D5: 2014/15 | E5: 2015/16 | F5: 2016/17 | G5: 2017/18
A6: Fazenda Planalto | B6: 7795 | C6: 7483 | D6: 10660 | E6: 13617 | F6: 12883 | G6: 13426
A7: Fazenda Pamplona | B7: 6522 | C7: 5902 | D7: 6567 | E7: 8312 | F7: 7880 | G7: 8082
A8: Fazenda Planeste | B8: 9821 | C8: 7371 | D8: 8241 | E8: 8358 | F8: 8831 | G8: 9594
A9: Fazenda Panorama | B9: 7989 | C9: 5372 | D9: 5792 | E9: 6119 | F9: 6324 | G9: 6884
A10: Fazenda Piratini | B10: 3466 | C10: 2818 | D10: 3235 | E10: 3602 | F10: 4044 | G10: 4044
A11: Fazenda Palmares | B11: 7902 | C11: 7315 | D11: 7608 | E11: 10130 | F11: 9015 | G11: 8421
A12: Fazenda Paiaguás | B12: 9251 | C12: 8677 | D12: 15146 | E12: 17733 | F12: 17954 | G12: 11862
A13: Fazenda Pejuçara | B13: 1287 | C13: 1207
A14: Fazenda Paineira | B14: 2533 | C14: 1965 | D14: 2688
A15: Fazenda Parceiro | B15: 2962 | C15: 2245 | D15: 657 | E15: 1217 | F15: 1136 | G15: 162
A16: Fazenda Perdizes | B16: 5276 | C16: 4830 | D16: 5172 | E16: 5930 | F16: 6274 | G16: 5326
A17: Fazenda Parnaíba | D17: 151 | E17: 159 | F17: 14124 | G17: 12614
A18: Fazenda Parnaguá | C18: 2100 | D18: 0 | E18: 586 | F18: 1064 | G18: 1420
A19: Fazenda Planorte | E19: 0 | F19: 14708 | G19: 12637
A20: Total (soma das fazendas) | B20: =SUM(B6:B19) -> 64804 | C20: =SUM(C6:C19) -> 57285 | D20: =SUM(D6:D19) -> 65917 | E20: =SUM(E6:E19) -> 75763 | F20: =SUM(F6:F19) -> 104237 | G20: =SUM(G6:G19) -> 94472
A21: Total reportado na nota | B21: 64804 | C21: 57285 | D21: 65917 | E21: 75303 | F21: 104237 | G21: 94452
A22: Diferença (soma – reportado) | B22: =B20-B21 -> 0 | C22: =C20-C21 -> 0 | D22: =D20-D21 -> 0 | E22: =E20-E21 -> 460 | F22: =F20-F21 -> 0 | G22: =G20-G21 -> 20
A23: Variação % do total reportado a.a. | C23: =C21/B21-1 -> -0.11602679 | D23: =D21/C21-1 -> 0.15068517 | E23: =E21/D21-1 -> 0.14239119 | F23: =F21/E21-1 -> 0.38423436 | G23: =G21/F21-1 -> -0.093872617
A24: Paiaguás + Pejuçara (série comparável) | B24: =B12+B13 -> 10538 | C24: =C12+C13 -> 9884 | D24: =D12+D13 -> 15146 | E24: =E12+E13 -> 17733 | F24: =F12+F13 -> 17954 | G24: =G12+G13 -> 11862

Sheet Base longa
A1: Fazenda | B1: Ano (31/dez) | C1: Safra | D1: Arrendamento (R$ mil)
A2: Fazenda Planalto | B2: 2012 | C2: 2012/13 | D2: ='Série Temporal'!B6 -> 7795
A3: Fazenda Planalto | B3: 2013 | C3: 2013/14 | D3: ='Série Temporal'!C6 -> 7483
A4: Fazenda Planalto | B4: 2014 | C4: 2014/15 | D4: ='Série Temporal'!D6 -> 10660
A5: Fazenda Planalto | B5: 2015 | C5: 2015/16 | D5: ='Série Temporal'!E6 -> 13617
A6: Fazenda Planalto | B6: 2016 | C6: 2016/17 | D6: ='Série Temporal'!F6 -> 12883
A7: Fazenda Planalto | B7: 2017 | C7: 2017/18 | D7: ='Série Temporal'!G6 -> 13426
A8: Fazenda Pamplona | B8: 2012 | C8: 2012/13 | D8: ='Série Temporal'!B7 -> 6522
A9: Fazenda Pamplona | B9: 2013 | C9: 2013/14 | D9: ='Série Temporal'!C7 -> 5902
A10: Fazenda Pamplona | B10: 2014 | C10: 2014/15 | D10: ='Série Temporal'!D7 -> 6567
A11: Fazenda Pamplona | B11: 2015 | C11: 2015/16 | D11: ='Série Temporal'!E7 -> 8312
A12: Fazenda Pamplona | B12: 2016 | C12: 2016/17 | D12: ='Série Temporal'!F7 -> 7880
A13: Fazenda Pamplona | B13: 2017 | C13: 2017/18 | D13: ='Série Temporal'!G7 -> 8082
A14: Fazenda Planeste | B14: 2012 | C14: 2012/13 | D14: ='Série Temporal'!B8 -> 9821
A15: Fazenda Planeste | B15: 2013 | C15: 2013/14 | D15: ='Série Temporal'!C8 -> 7371
A16: Fazenda Planeste | B16: 2014 | C16: 2014/15 | D16: ='Série Temporal'!D8 -> 8241
A17: Fazenda Planeste | B17: 2015 | C17: 2015/16 | D17: ='Série Temporal'!E8 -> 8358
A18: Fazenda Planeste | B18: 2016 | C18: 2016/17 | D18: ='Série Temporal'!F8 -> 8831
A19: Fazenda Planeste | B19: 2017 | C19: 2017/18 | D19: ='Série Temporal'!G8 -> 9594
A20: Fazenda Panorama | B20: 2012 | C20: 2012/13 | D20: ='Série Temporal'!B9 -> 7989
A21: Fazenda Panorama | B21: 2013 | C21: 2013/14 | D21: ='Série Temporal'!C9 -> 5372
A22: Fazenda Panorama | B22: 2014 | C22: 2014/15 | D22: ='Série Temporal'!D9 -> 5792
A23: Fazenda Panorama | B23: 2015 | C23: 2015/16 | D23: ='Série Temporal'!E9 -> 6119
A24: Fazenda Panorama | B24: 2016 | C24: 2016/17 | D24: ='Série Temporal'!F9 -> 6324
A25: Fazenda Panorama | B25: 2017 | C25: 2017/18 | D25: ='Série Temporal'!G9 -> 6884
A26: Fazenda Piratini | B26: 2012 | C26: 2012/13 | D26: ='Série Temporal'!B10 -> 3466
A27: Fazenda Piratini | B27: 2013 | C27: 2013/14 | D27: ='Série Temporal'!C10 -> 2818
A28: Fazenda Piratini | B28: 2014 | C28: 2014/15 | D28: ='Série Temporal'!D10 -> 3235
A29: Fazenda Piratini | B29: 2015 | C29: 2015/16 | D29: ='Série Temporal'!E10 -> 3602
A30: Fazenda Piratini | B30: 2016 | C30: 2016/17 | D30: ='Série Temporal'!F10 -> 4044
A31: Fazenda Piratini | B31: 2017 | C31: 2017/18 | D31: ='Série Temporal'!G10 -> 4044
A32: Fazenda Palmares | B32: 2012 | C32: 2012/13 | D32: ='Série Temporal'!B11 -> 7902
A33: Fazenda Palmares | B33: 2013 | C33: 2013/14 | D33: ='Série Temporal'!C11 -> 7315
A34: Fazenda Palmares | B34: 2014 | C34: 2014/15 | D34: ='Série Temporal'!D11 -> 7608
A35: Fazenda Palmares | B35: 2015 | C35: 2015/16 | D35: ='Série Temporal'!E11 -> 10130
A36: Fazenda Palmares | B36: 2016 | C36: 2016/17 | D36: ='Série Temporal'!F11 -> 9015
A37: Fazenda Palmares | B37: 2017 | C37: 2017/18 | D37: ='Série Temporal'!G11 -> 8421
A38: Fazenda Paiaguás | B38: 2012 | C38: 2012/13 | D38: ='Série Temporal'!B12 -> 9251
A39: Fazenda Paiaguás | B39: 2013 | C39: 2013/14 | D39: ='Série Temporal'!C12 -> 8677
A40: Fazenda Paiaguás | B40: 2014 | C40: 2014/15 | D40: ='Série Temporal'!D12 -> 15146
...

Sheet Notas
A1: Notas e premissas
A2: 1) A imagem cobre as notas de 2012 a 2017 (safras 2012/13 a 2017/18). Não há dados de 2021 na imagem; a série começa em 2012 (assumi que '2021' era erro de digitação para 2012).
A3: 2) Valores em R$ mil (notas 'em milhares de Reais'), preço anual do arrendamento em 31/dez de cada ano, referente à safra seguinte.
A4: 3) Fonte dos anos: 2012 = tabela safra 2012/13; 2013 = tabela safra 2013/14 (total 57.285); 2014 = tabela safra 2014/15 (total 65.917); 2015 e 2016 = tabelas safra 2015/16 (total 75.303) e 2016/17 (total 104.237); 2017 = tabela safra 2017/18 (total 94.452). Colunas de comparativo foram usadas para conferência.
A5: 4) Pejuçara: aparece separada em 2012–2013; a partir da tabela de 2014 foi incorporada a Paiaguás (Paiaguás 2013 reapresentado = 9.884 = 8.677 + 1.207). Use a linha 'Paiaguás + Pejuçara' para série comparável.
A6: 5) Paineira: listada em 2012–2014; não aparece nas tabelas de 2015 em diante. '-' nas notas foi digitado como 0; célula vazia = fazenda não listada naquele ano.
A7: 6) 'Fazenda Parnaguá' e 'Fazenda Planorte' foram lidas das imagens (grafia borrada).
A8: 7) A imagem tem baixa resolução. Conciliação com o total reportado: 2012, 2013, 2014 e 2016 fecham exatamente; 2015 difere em +460 (provável Planalto = 13.157 em vez de 13.617) e 2017 difere em +20 (um dígito de algum valor em negrito). Células amarelas = conferir no PDF original.
